[2025-07-10T15:18:34.319+0000] {taskinstance.py:1956} INFO - Dependencies all met for dep_context=non-requeueable deps ti=<TaskInstance: northwind.gerar_csv_validacao manual__2025-07-10T15:17:11.680336+00:00 [queued]>
[2025-07-10T15:18:34.327+0000] {taskinstance.py:1956} INFO - Dependencies all met for dep_context=requeueable deps ti=<TaskInstance: northwind.gerar_csv_validacao manual__2025-07-10T15:17:11.680336+00:00 [queued]>
[2025-07-10T15:18:34.328+0000] {taskinstance.py:2170} INFO - Starting attempt 1 of 2
[2025-07-10T15:18:34.339+0000] {taskinstance.py:2191} INFO - Executing <Task(PythonOperator): gerar_csv_validacao> on 2025-07-10 15:17:11.680336+00:00
[2025-07-10T15:18:34.345+0000] {standard_task_runner.py:60} INFO - Started process 195 to run task
[2025-07-10T15:18:34.348+0000] {standard_task_runner.py:87} INFO - Running: ['***', 'tasks', 'run', 'northwind', 'gerar_csv_validacao', 'manual__2025-07-10T15:17:11.680336+00:00', '--job-id', '108', '--raw', '--subdir', 'DAGS_FOLDER/northwind.py', '--cfg-path', '/tmp/tmpkwuz644o']
[2025-07-10T15:18:34.350+0000] {standard_task_runner.py:88} INFO - Job 108: Subtask gerar_csv_validacao
[2025-07-10T15:18:34.396+0000] {task_command.py:423} INFO - Running <TaskInstance: northwind.gerar_csv_validacao manual__2025-07-10T15:17:11.680336+00:00 [running]> on host 8ddbac0a6dc1
[2025-07-10T15:18:34.476+0000] {taskinstance.py:2480} INFO - Exporting env vars: AIRFLOW_CTX_DAG_EMAIL='lrbf@cin.ufpe.br' AIRFLOW_CTX_DAG_OWNER='***' AIRFLOW_CTX_DAG_ID='northwind' AIRFLOW_CTX_TASK_ID='gerar_csv_validacao' AIRFLOW_CTX_EXECUTION_DATE='2025-07-10T15:17:11.680336+00:00' AIRFLOW_CTX_TRY_NUMBER='1' AIRFLOW_CTX_DAG_RUN_ID='manual__2025-07-10T15:17:11.680336+00:00'
[2025-07-10T15:18:34.484+0000] {base.py:83} INFO - Using connection ID '***_target_conn' for task execution.
[2025-07-10T15:18:34.656+0000] {logging_mixin.py:188} INFO - Erro ao gerar o CSV: [Errno 21] Is a directory: '/opt/output_data'
[2025-07-10T15:18:34.657+0000] {taskinstance.py:2698} ERROR - Task failed with exception
Traceback (most recent call last):
  File "/home/airflow/.local/lib/python3.10/site-packages/airflow/models/taskinstance.py", line 433, in _execute_task
    result = execute_callable(context=context, **execute_callable_kwargs)
  File "/home/airflow/.local/lib/python3.10/site-packages/airflow/operators/python.py", line 199, in execute
    return_value = self.execute_callable()
  File "/home/airflow/.local/lib/python3.10/site-packages/airflow/operators/python.py", line 216, in execute_callable
    return self.python_callable(*self.op_args, **self.op_kwargs)
  File "/opt/airflow/dags/northwind.py", line 60, in _export_query_to_csv
    with open(output_path, 'w', newline='') as csvfile:
IsADirectoryError: [Errno 21] Is a directory: '/opt/output_data'
[2025-07-10T15:18:34.667+0000] {taskinstance.py:1138} INFO - Marking task as UP_FOR_RETRY. dag_id=northwind, task_id=gerar_csv_validacao, execution_date=20250710T151711, start_date=20250710T151834, end_date=20250710T151834
[2025-07-10T15:18:34.680+0000] {standard_task_runner.py:107} ERROR - Failed to execute job 108 for task gerar_csv_validacao ([Errno 21] Is a directory: '/opt/output_data'; 195)
[2025-07-10T15:18:34.696+0000] {local_task_job_runner.py:234} INFO - Task exited with return code 1
[2025-07-10T15:18:34.712+0000] {taskinstance.py:3280} INFO - 0 downstream tasks scheduled from follow-on schedule check
