[2025-07-01T22:20:27.367+0000] {taskinstance.py:1956} INFO - Dependencies all met for dep_context=non-requeueable deps ti=<TaskInstance: northwind.carregamento_postgres manual__2025-07-01T22:00:09.160190+00:00 [queued]>
[2025-07-01T22:20:27.387+0000] {taskinstance.py:1956} INFO - Dependencies all met for dep_context=requeueable deps ti=<TaskInstance: northwind.carregamento_postgres manual__2025-07-01T22:00:09.160190+00:00 [queued]>
[2025-07-01T22:20:27.387+0000] {taskinstance.py:2170} INFO - Starting attempt 2 of 2
[2025-07-01T22:20:27.410+0000] {taskinstance.py:2191} INFO - Executing <Task(DockerOperator): carregamento_postgres> on 2025-07-01 22:00:09.160190+00:00
[2025-07-01T22:20:27.419+0000] {standard_task_runner.py:60} INFO - Started process 212 to run task
[2025-07-01T22:20:27.428+0000] {standard_task_runner.py:87} INFO - Running: ['***', 'tasks', 'run', 'northwind', 'carregamento_postgres', 'manual__2025-07-01T22:00:09.160190+00:00', '--job-id', '18', '--raw', '--subdir', 'DAGS_FOLDER/northwind.py', '--cfg-path', '/tmp/tmprzw3bo4d']
[2025-07-01T22:20:27.443+0000] {standard_task_runner.py:88} INFO - Job 18: Subtask carregamento_postgres
[2025-07-02T01:02:15.008+0000] {task_command.py:423} INFO - Running <TaskInstance: northwind.carregamento_postgres manual__2025-07-01T22:00:09.160190+00:00 [running]> on host e62fc41f1c39
[2025-07-02T01:02:15.186+0000] {taskinstance.py:2480} INFO - Exporting env vars: AIRFLOW_CTX_DAG_EMAIL='lrbf@cin.ufpe.br' AIRFLOW_CTX_DAG_OWNER='***' AIRFLOW_CTX_DAG_ID='northwind' AIRFLOW_CTX_TASK_ID='carregamento_postgres' AIRFLOW_CTX_EXECUTION_DATE='2025-07-01T22:00:09.160190+00:00' AIRFLOW_CTX_TRY_NUMBER='2' AIRFLOW_CTX_DAG_RUN_ID='manual__2025-07-01T22:00:09.160190+00:00'
[2025-07-02T01:02:15.903+0000] {docker.py:359} INFO - Starting docker container from image meltano:latest
[2025-07-02T01:02:19.615+0000] {docker.py:429} INFO - Running meltano install...
[2025-07-02T01:02:22.539+0000] {docker.py:429} INFO - [2m2025-07-02T01:02:22.538208Z[0m [[32m[1minfo     [0m] [1mInstalling 7 plugins          [0m
[2025-07-02T01:02:22.550+0000] {docker.py:429} INFO - [2m2025-07-02T01:02:22.550029Z[0m [[32m[1minfo     [0m] [1mInstalling extractor 'tap-postgres'[0m
[2025-07-02T01:02:22.572+0000] {docker.py:429} INFO - [2m2025-07-02T01:02:22.572147Z[0m [[32m[1minfo     [0m] [1mInstalling extractor 'tap-csv'[0m
[2025-07-02T01:02:22.599+0000] {docker.py:429} INFO - [2m2025-07-02T01:02:22.598755Z[0m [[32m[1minfo     [0m] [1mInstalling extractor 'tap-csv-latest'[0m
[2025-07-02T01:02:22.640+0000] {docker.py:429} INFO - [2m2025-07-02T01:02:22.639370Z[0m [[32m[1minfo     [0m] [1mInstalling loader 'target-postgres'[0m
[2025-07-02T01:02:22.694+0000] {docker.py:429} INFO - [2m2025-07-02T01:02:22.693490Z[0m [[32m[1minfo     [0m] [1mInstalling loader 'target-csv'[0m
[2025-07-02T01:02:22.861+0000] {docker.py:429} INFO - [2m2025-07-02T01:02:22.859784Z[0m [[32m[1minfo     [0m] [1mInstalling loader 'target-csv-postgres'[0m
[2025-07-02T01:02:22.947+0000] {docker.py:429} INFO - [2m2025-07-02T01:02:22.946190Z[0m [[32m[1minfo     [0m] [1mInstalling loader 'target-csv-csv'[0m
[2025-07-02T01:02:33.752+0000] {docker.py:429} INFO - [2m2025-07-02T01:02:33.744337Z[0m [[32m[1minfo     [0m] [1mInstalled loader 'target-postgres'[0m
[2025-07-02T01:02:33.811+0000] {docker.py:429} INFO - [2m2025-07-02T01:02:33.811057Z[0m [[32m[1minfo     [0m] [1mInstalled extractor 'tap-postgres'[0m
[2025-07-02T01:02:41.421+0000] {docker.py:429} INFO - [2m2025-07-02T01:02:41.420853Z[0m [[32m[1minfo     [0m] [1mLogged pip install output to /opt/meltano/.meltano/logs/pip/extractors/tap-csv-latest/pip.log[0m
[2025-07-02T01:02:41.422+0000] {docker.py:429} INFO - [2m2025-07-02T01:02:41.421709Z[0m [[31m[1merror    [0m] [1mExtractor 'tap-csv-latest' could not be installed: Failed to install plugin 'tap-csv-latest'.[0m [36mdetails[0m=[35m"Collecting git+https://github.com/MeltanoLabs/tap-csv.git\n  Cloning https://github.com/MeltanoLabs/tap-csv.git to /tmp/pip-req-build-9up70lv4\n  Running command git clone --filter=blob:none --quiet https://github.com/MeltanoLabs/tap-csv.git /tmp/pip-req-build-9up70lv4\n  fatal: unable to access 'https://github.com/MeltanoLabs/tap-csv.git/': Could not resolve host: github.com\n  error: subprocess-exited-with-error\n  \n  Ã— git clone --filter=blob:none --quiet https://github.com/MeltanoLabs/tap-csv.git /tmp/pip-req-build-9up70lv4 did not run successfully.\n  â”‚ exit code: 128\n  â•°â”€> See above for output.\n  \n  note: This error originates from a subprocess, and is likely not a problem with pip.\nerror: subprocess-exited-with-error\n\nÃ— git clone --filter=blob:none --quiet https://github.com/MeltanoLabs/tap-csv.git /tmp/pip-req-build-9up70lv4 did not run successfully.\nâ”‚ exit code: 128\nâ•°â”€> See above for output.\n\nnote: This error originates from a subprocess, and is likely not a problem with pip.\n"[0m
[2025-07-02T01:02:41.423+0000] {docker.py:429} INFO - [2m2025-07-02T01:02:41.422920Z[0m [[32m[1minfo     [0m] [1mLogged pip install output to /opt/meltano/.meltano/logs/pip/extractors/tap-csv/pip.log[0m
[2025-07-02T01:02:41.424+0000] {docker.py:429} INFO - [2m2025-07-02T01:02:41.423257Z[0m [[31m[1merror    [0m] [1mExtractor 'tap-csv' could not be installed: Failed to install plugin 'tap-csv'.[0m [36mdetails[0m=[35m"Collecting git+https://github.com/MeltanoLabs/tap-csv.git\n  Cloning https://github.com/MeltanoLabs/tap-csv.git to /tmp/pip-req-build-5i3019dc\n  Running command git clone --filter=blob:none --quiet https://github.com/MeltanoLabs/tap-csv.git /tmp/pip-req-build-5i3019dc\n  fatal: unable to access 'https://github.com/MeltanoLabs/tap-csv.git/': Could not resolve host: github.com\n  error: subprocess-exited-with-error\n  \n  Ã— git clone --filter=blob:none --quiet https://github.com/MeltanoLabs/tap-csv.git /tmp/pip-req-build-5i3019dc did not run successfully.\n  â”‚ exit code: 128\n  â•°â”€> See above for output.\n  \n  note: This error originates from a subprocess, and is likely not a problem with pip.\nerror: subprocess-exited-with-error\n\nÃ— git clone --filter=blob:none --quiet https://github.com/MeltanoLabs/tap-csv.git /tmp/pip-req-build-5i3019dc did not run successfully.\nâ”‚ exit code: 128\nâ•°â”€> See above for output.\n\nnote: This error originates from a subprocess, and is likely not a problem with pip.\n"[0m
[2025-07-02T01:02:41.450+0000] {docker.py:429} INFO - [2m2025-07-02T01:02:41.449670Z[0m [[32m[1minfo     [0m] [1mLogged pip install output to /opt/meltano/.meltano/logs/pip/loaders/target-csv-postgres/pip.log[0m
[2025-07-02T01:02:41.450+0000] {docker.py:429} INFO - [2m2025-07-02T01:02:41.449997Z[0m [[31m[1merror    [0m] [1mLoader 'target-csv-postgres' could not be installed: Failed to install plugin 'target-csv-postgres'.[0m [36mdetails[0m=[35m"Collecting git+https://github.com/roboberto1403/target-csv-1\n  Cloning https://github.com/roboberto1403/target-csv-1 to /tmp/pip-req-build-qb5cewmb\n  Running command git clone --filter=blob:none --quiet https://github.com/roboberto1403/target-csv-1 /tmp/pip-req-build-qb5cewmb\n  fatal: unable to access 'https://github.com/roboberto1403/target-csv-1/': Could not resolve host: github.com\n  error: subprocess-exited-with-error\n  \n  Ã— git clone --filter=blob:none --quiet https://github.com/roboberto1403/target-csv-1 /tmp/pip-req-build-qb5cewmb did not run successfully.\n  â”‚ exit code: 128\n  â•°â”€> See above for output.\n  \n  note: This error originates from a subprocess, and is likely not a problem with pip.\nerror: subprocess-exited-with-error\n\nÃ— git clone --filter=blob:none --quiet https://github.com/roboberto1403/target-csv-1 /tmp/pip-req-build-qb5cewmb did not run successfully.\nâ”‚ exit code: 128\nâ•°â”€> See above for output.\n\nnote: This error originates from a subprocess, and is likely not a problem with pip.\n"[0m
[2025-07-02T01:02:41.465+0000] {docker.py:429} INFO - [2m2025-07-02T01:02:41.464948Z[0m [[32m[1minfo     [0m] [1mLogged pip install output to /opt/meltano/.meltano/logs/pip/loaders/target-csv/pip.log[0m
[2m2025-07-02T01:02:41.465206Z[0m [[31m[1merror    [0m] [1mLoader 'target-csv' could not be installed: Failed to install plugin 'target-csv'.[0m [36mdetails[0m=[35m"Collecting git+https://github.com/singer-io/target-csv.git\n  Cloning https://github.com/singer-io/target-csv.git to /tmp/pip-req-build-8g2yeiu2\n  Running command git clone --filter=blob:none --quiet https://github.com/singer-io/target-csv.git /tmp/pip-req-build-8g2yeiu2\n  fatal: unable to access 'https://github.com/singer-io/target-csv.git/': Could not resolve host: github.com\n  error: subprocess-exited-with-error\n  \n  Ã— git clone --filter=blob:none --quiet https://github.com/singer-io/target-csv.git /tmp/pip-req-build-8g2yeiu2 did not run successfully.\n  â”‚ exit code: 128\n  â•°â”€> See above for output.\n  \n  note: This error originates from a subprocess, and is likely not a problem with pip.\nerror: subprocess-exited-with-error\n\nÃ— git clone --filter=blob:none --quiet https://github.com/singer-io/target-csv.git /tmp/pip-req-build-8g2yeiu2 did not run successfully.\nâ”‚ exit code: 128\nâ•°â”€> See above for output.\n\nnote: This error originates from a subprocess, and is likely not a problem with pip.\n"[0m
[2025-07-02T01:02:41.763+0000] {docker.py:429} INFO - [2m2025-07-02T01:02:41.762316Z[0m [[32m[1minfo     [0m] [1mLogged pip install output to /opt/meltano/.meltano/logs/pip/loaders/target-csv-csv/pip.log[0m
[2m2025-07-02T01:02:41.762644Z[0m [[31m[1merror    [0m] [1mLoader 'target-csv-csv' could not be installed: Failed to install plugin 'target-csv-csv'.[0m [36mdetails[0m=[35m"Collecting git+https://github.com/roboberto1403/target-csv-2\n  Cloning https://github.com/roboberto1403/target-csv-2 to /tmp/pip-req-build-mh774net\n  Running command git clone --filter=blob:none --quiet https://github.com/roboberto1403/target-csv-2 /tmp/pip-req-build-mh774net\n  fatal: unable to access 'https://github.com/roboberto1403/target-csv-2/': Could not resolve host: github.com\n  error: subprocess-exited-with-error\n  \n  Ã— git clone --filter=blob:none --quiet https://github.com/roboberto1403/target-csv-2 /tmp/pip-req-build-mh774net did not run successfully.\n  â”‚ exit code: 128\n  â•°â”€> See above for output.\n  \n  note: This error originates from a subprocess, and is likely not a problem with pip.\nerror: subprocess-exited-with-error\n\nÃ— git clone --filter=blob:none --quiet https://github.com/roboberto1403/target-csv-2 /tmp/pip-req-build-mh774net did not run successfully.\nâ”‚ exit code: 128\nâ•°â”€> See above for output.\n\nnote: This error originates from a subprocess, and is likely not a problem with pip.\n"[0m
[2025-07-02T01:02:41.764+0000] {docker.py:429} INFO - [2m2025-07-02T01:02:41.763292Z[0m [[33m[1mwarning  [0m] [1mInstalled 2/7 plugins         [0m
[2025-07-02T01:02:41.772+0000] {docker.py:429} INFO - Need help fixing this problem? Visit http://melta.no/ for troubleshooting steps, or to
join our friendly Slack community.

Failed to install plugin(s)
[2025-07-02T01:02:49.793+0000] {docker.py:429} INFO - [2m2025-07-02T01:02:49.792061Z[0m [[33m[1mwarning  [0m] [1mRetrying (Retry(total=2, connect=None, read=None, redirect=None, status=0)) after connection broken by 'NewConnectionError('<urllib3.connection.HTTPSConnection object at 0x74e3314cf6d0>: Failed to establish a new connection: [Errno -3] Temporary failure in name resolution')': /com.snowplowanalytics.snowplow/tp2[0m
[2025-07-02T01:02:57.800+0000] {docker.py:429} INFO - [2m2025-07-02T01:02:57.800141Z[0m [[33m[1mwarning  [0m] [1mRetrying (Retry(total=1, connect=None, read=None, redirect=None, status=0)) after connection broken by 'NewConnectionError('<urllib3.connection.HTTPSConnection object at 0x74e3314cf2e0>: Failed to establish a new connection: [Errno -3] Temporary failure in name resolution')': /com.snowplowanalytics.snowplow/tp2[0m
[2025-07-02T01:03:05.803+0000] {docker.py:429} INFO - [2m2025-07-02T01:03:05.803423Z[0m [[33m[1mwarning  [0m] [1mRetrying (Retry(total=0, connect=None, read=None, redirect=None, status=0)) after connection broken by 'NewConnectionError('<urllib3.connection.HTTPSConnection object at 0x74e3314dafd0>: Failed to establish a new connection: [Errno -3] Temporary failure in name resolution')': /com.snowplowanalytics.snowplow/tp2[0m
[2025-07-02T01:03:14.345+0000] {docker.py:429} INFO - Meltano install failed. Check logs above.
[2025-07-02T01:03:14.727+0000] {taskinstance.py:2698} ERROR - Task failed with exception
Traceback (most recent call last):
  File "/home/airflow/.local/lib/python3.10/site-packages/airflow/models/taskinstance.py", line 433, in _execute_task
    result = execute_callable(context=context, **execute_callable_kwargs)
  File "/home/airflow/.local/lib/python3.10/site-packages/airflow/providers/docker/operators/docker.py", line 502, in execute
    return self._run_image()
  File "/home/airflow/.local/lib/python3.10/site-packages/airflow/providers/docker/operators/docker.py", line 376, in _run_image
    return self._run_image_with_mounts(self.mounts, add_tmp_variable=False)
  File "/home/airflow/.local/lib/python3.10/site-packages/airflow/providers/docker/operators/docker.py", line 437, in _run_image_with_mounts
    raise DockerContainerFailedException(f"Docker container failed: {result!r}", logs=log_lines)
airflow.providers.docker.exceptions.DockerContainerFailedException: Docker container failed: {'StatusCode': 1}
[2025-07-02T01:03:14.750+0000] {taskinstance.py:1138} INFO - Marking task as FAILED. dag_id=northwind, task_id=carregamento_postgres, execution_date=20250701T220009, start_date=20250701T222027, end_date=20250702T010314
[2025-07-02T01:03:14.858+0000] {logging_mixin.py:188} WARNING - /home/***/.local/lib/python3.10/site-packages/***/utils/email.py:154 RemovedInAirflow3Warning: Fetching SMTP credentials from configuration variables will be deprecated in a future release. Please set credentials using a connection instead.
[2025-07-02T01:03:14.859+0000] {configuration.py:1046} WARNING - section/key [smtp/smtp_user] not found in config
[2025-07-02T01:03:14.860+0000] {email.py:270} INFO - Email alerting: attempt 1
[2025-07-02T01:03:14.869+0000] {configuration.py:1046} WARNING - section/key [smtp/smtp_user] not found in config
[2025-07-02T01:03:14.870+0000] {email.py:270} INFO - Email alerting: attempt 1
[2025-07-02T01:03:14.871+0000] {taskinstance.py:826} ERROR - Failed to send email to: ['lrbf@cin.ufpe.br']
Traceback (most recent call last):
  File "/home/airflow/.local/lib/python3.10/site-packages/airflow/models/taskinstance.py", line 2334, in _run_raw_task
    self._execute_task_with_callbacks(context, test_mode, session=session)
  File "/home/airflow/.local/lib/python3.10/site-packages/airflow/models/taskinstance.py", line 2499, in _execute_task_with_callbacks
    result = self._execute_task(context, task_orig)
  File "/home/airflow/.local/lib/python3.10/site-packages/airflow/models/taskinstance.py", line 2516, in _execute_task
    return _execute_task(self, context, task_orig)
  File "/home/airflow/.local/lib/python3.10/site-packages/airflow/models/taskinstance.py", line 433, in _execute_task
    result = execute_callable(context=context, **execute_callable_kwargs)
  File "/home/airflow/.local/lib/python3.10/site-packages/airflow/providers/docker/operators/docker.py", line 502, in execute
    return self._run_image()
  File "/home/airflow/.local/lib/python3.10/site-packages/airflow/providers/docker/operators/docker.py", line 376, in _run_image
    return self._run_image_with_mounts(self.mounts, add_tmp_variable=False)
  File "/home/airflow/.local/lib/python3.10/site-packages/airflow/providers/docker/operators/docker.py", line 437, in _run_image_with_mounts
    raise DockerContainerFailedException(f"Docker container failed: {result!r}", logs=log_lines)
airflow.providers.docker.exceptions.DockerContainerFailedException: Docker container failed: {'StatusCode': 1}

During handling of the above exception, another exception occurred:

Traceback (most recent call last):
  File "/home/airflow/.local/lib/python3.10/site-packages/airflow/models/taskinstance.py", line 1000, in _email_alert
    send_email(task.email, subject, html_content)
  File "/home/airflow/.local/lib/python3.10/site-packages/airflow/utils/email.py", line 80, in send_email
    return backend(
  File "/home/airflow/.local/lib/python3.10/site-packages/airflow/utils/email.py", line 154, in send_email_smtp
    send_mime_email(e_from=mail_from, e_to=recipients, mime_msg=msg, conn_id=conn_id, dryrun=dryrun)
  File "/home/airflow/.local/lib/python3.10/site-packages/airflow/utils/email.py", line 272, in send_mime_email
    smtp_conn = _get_smtp_connection(smtp_host, smtp_port, smtp_timeout, smtp_ssl)
  File "/home/airflow/.local/lib/python3.10/site-packages/airflow/utils/email.py", line 316, in _get_smtp_connection
    return smtplib.SMTP(host=host, port=port, timeout=timeout)
  File "/usr/local/lib/python3.10/smtplib.py", line 255, in __init__
    (code, msg) = self.connect(host, port)
  File "/usr/local/lib/python3.10/smtplib.py", line 341, in connect
    self.sock = self._get_socket(host, port, self.timeout)
  File "/usr/local/lib/python3.10/smtplib.py", line 312, in _get_socket
    return socket.create_connection((host, port), timeout,
  File "/usr/local/lib/python3.10/socket.py", line 845, in create_connection
    raise err
  File "/usr/local/lib/python3.10/socket.py", line 833, in create_connection
    sock.connect(sa)
ConnectionRefusedError: [Errno 111] Connection refused

During handling of the above exception, another exception occurred:

Traceback (most recent call last):
  File "/home/airflow/.local/lib/python3.10/site-packages/airflow/models/taskinstance.py", line 824, in _handle_failure
    task_instance.email_alert(error, failure_context["task"])
  File "/home/airflow/.local/lib/python3.10/site-packages/airflow/models/taskinstance.py", line 2946, in email_alert
    _email_alert(task_instance=self, exception=exception, task=task)
  File "/home/airflow/.local/lib/python3.10/site-packages/airflow/models/taskinstance.py", line 1002, in _email_alert
    send_email(task.email, subject, html_content_err)
  File "/home/airflow/.local/lib/python3.10/site-packages/airflow/utils/email.py", line 80, in send_email
    return backend(
  File "/home/airflow/.local/lib/python3.10/site-packages/airflow/utils/email.py", line 154, in send_email_smtp
    send_mime_email(e_from=mail_from, e_to=recipients, mime_msg=msg, conn_id=conn_id, dryrun=dryrun)
  File "/home/airflow/.local/lib/python3.10/site-packages/airflow/utils/email.py", line 272, in send_mime_email
    smtp_conn = _get_smtp_connection(smtp_host, smtp_port, smtp_timeout, smtp_ssl)
  File "/home/airflow/.local/lib/python3.10/site-packages/airflow/utils/email.py", line 316, in _get_smtp_connection
    return smtplib.SMTP(host=host, port=port, timeout=timeout)
  File "/usr/local/lib/python3.10/smtplib.py", line 255, in __init__
    (code, msg) = self.connect(host, port)
  File "/usr/local/lib/python3.10/smtplib.py", line 341, in connect
    self.sock = self._get_socket(host, port, self.timeout)
  File "/usr/local/lib/python3.10/smtplib.py", line 312, in _get_socket
    return socket.create_connection((host, port), timeout,
  File "/usr/local/lib/python3.10/socket.py", line 845, in create_connection
    raise err
  File "/usr/local/lib/python3.10/socket.py", line 833, in create_connection
    sock.connect(sa)
ConnectionRefusedError: [Errno 111] Connection refused
[2025-07-02T01:03:14.903+0000] {standard_task_runner.py:107} ERROR - Failed to execute job 18 for task carregamento_postgres (Docker container failed: {'StatusCode': 1}; 212)
[2025-07-02T01:03:14.953+0000] {local_task_job_runner.py:234} INFO - Task exited with return code 1
[2025-07-02T01:03:15.007+0000] {taskinstance.py:3280} INFO - 0 downstream tasks scheduled from follow-on schedule check
