[2025-06-27T22:53:05.906+0000] {taskinstance.py:1956} INFO - Dependencies all met for dep_context=non-requeueable deps ti=<TaskInstance: northwind.extração_postgres manual__2025-06-27T22:53:04.429010+00:00 [queued]>
[2025-06-27T22:53:05.923+0000] {taskinstance.py:1956} INFO - Dependencies all met for dep_context=requeueable deps ti=<TaskInstance: northwind.extração_postgres manual__2025-06-27T22:53:04.429010+00:00 [queued]>
[2025-06-27T22:53:05.923+0000] {taskinstance.py:2170} INFO - Starting attempt 1 of 2
[2025-06-27T22:53:05.944+0000] {taskinstance.py:2191} INFO - Executing <Task(DockerOperator): extração_postgres> on 2025-06-27 22:53:04.429010+00:00
[2025-06-27T22:53:05.948+0000] {standard_task_runner.py:60} INFO - Started process 326 to run task
[2025-06-27T22:53:05.952+0000] {standard_task_runner.py:87} INFO - Running: ['***', 'tasks', 'run', 'northwind', 'extração_postgres', 'manual__2025-06-27T22:53:04.429010+00:00', '--job-id', '5', '--raw', '--subdir', 'DAGS_FOLDER/dag.py', '--cfg-path', '/tmp/tmpnox1o1pr']
[2025-06-27T22:53:05.954+0000] {standard_task_runner.py:88} INFO - Job 5: Subtask extração_postgres
[2025-06-27T22:53:06.007+0000] {task_command.py:423} INFO - Running <TaskInstance: northwind.extração_postgres manual__2025-06-27T22:53:04.429010+00:00 [running]> on host 4e070cd4d905
[2025-06-27T22:53:06.175+0000] {taskinstance.py:2480} INFO - Exporting env vars: AIRFLOW_CTX_DAG_EMAIL='lrbf@cin.ufpe.br' AIRFLOW_CTX_DAG_OWNER='***' AIRFLOW_CTX_DAG_ID='northwind' AIRFLOW_CTX_TASK_ID='extração_postgres' AIRFLOW_CTX_EXECUTION_DATE='2025-06-27T22:53:04.429010+00:00' AIRFLOW_CTX_TRY_NUMBER='1' AIRFLOW_CTX_DAG_RUN_ID='manual__2025-06-27T22:53:04.429010+00:00'
[2025-06-27T22:53:06.439+0000] {docker.py:359} INFO - Starting docker container from image meltano:latest
[2025-06-27T22:53:06.527+0000] {taskinstance.py:2698} ERROR - Task failed with exception
Traceback (most recent call last):
  File "/home/airflow/.local/lib/python3.10/site-packages/docker/api/client.py", line 265, in _raise_for_status
    response.raise_for_status()
  File "/home/airflow/.local/lib/python3.10/site-packages/requests/models.py", line 1021, in raise_for_status
    raise HTTPError(http_error_msg, response=self)
requests.exceptions.HTTPError: 404 Client Error: Not Found for url: http+docker://localhost/v1.47/containers/213ae1a57045ac5375fa9ff8701cdcd459cf597c7f711b433cfd29d0227787d1/start

The above exception was the direct cause of the following exception:

Traceback (most recent call last):
  File "/home/airflow/.local/lib/python3.10/site-packages/airflow/models/taskinstance.py", line 433, in _execute_task
    result = execute_callable(context=context, **execute_callable_kwargs)
  File "/home/airflow/.local/lib/python3.10/site-packages/airflow/providers/docker/operators/docker.py", line 502, in execute
    return self._run_image()
  File "/home/airflow/.local/lib/python3.10/site-packages/airflow/providers/docker/operators/docker.py", line 376, in _run_image
    return self._run_image_with_mounts(self.mounts, add_tmp_variable=False)
  File "/home/airflow/.local/lib/python3.10/site-packages/airflow/providers/docker/operators/docker.py", line 423, in _run_image_with_mounts
    self.cli.start(self.container["Id"])
  File "/home/airflow/.local/lib/python3.10/site-packages/docker/utils/decorators.py", line 19, in wrapped
    return f(self, resource_id, *args, **kwargs)
  File "/home/airflow/.local/lib/python3.10/site-packages/docker/api/container.py", line 1135, in start
    self._raise_for_status(res)
  File "/home/airflow/.local/lib/python3.10/site-packages/docker/api/client.py", line 267, in _raise_for_status
    raise create_api_error_from_http_exception(e) from e
  File "/home/airflow/.local/lib/python3.10/site-packages/docker/errors.py", line 39, in create_api_error_from_http_exception
    raise cls(e, response=response, explanation=explanation) from e
docker.errors.NotFound: 404 Client Error for http+docker://localhost/v1.47/containers/213ae1a57045ac5375fa9ff8701cdcd459cf597c7f711b433cfd29d0227787d1/start: Not Found ("network airflow_meltano_network not found")
[2025-06-27T22:53:06.542+0000] {taskinstance.py:1138} INFO - Marking task as UP_FOR_RETRY. dag_id=northwind, task_id=extração_postgres, execution_date=20250627T225304, start_date=20250627T225305, end_date=20250627T225306
[2025-06-27T22:53:06.559+0000] {standard_task_runner.py:107} ERROR - Failed to execute job 5 for task extração_postgres (404 Client Error for http+docker://localhost/v1.47/containers/213ae1a57045ac5375fa9ff8701cdcd459cf597c7f711b433cfd29d0227787d1/start: Not Found ("network airflow_meltano_network not found"); 326)
[2025-06-27T22:53:06.571+0000] {local_task_job_runner.py:234} INFO - Task exited with return code 1
[2025-06-27T22:53:06.592+0000] {taskinstance.py:3280} INFO - 0 downstream tasks scheduled from follow-on schedule check
