[2025-07-01T13:16:29.494+0000] {taskinstance.py:1956} INFO - Dependencies all met for dep_context=non-requeueable deps ti=<TaskInstance: northwind.carregamento_postgres manual__2025-07-01T12:46:33.097030+00:00 [queued]>
[2025-07-01T13:16:29.517+0000] {taskinstance.py:1956} INFO - Dependencies all met for dep_context=requeueable deps ti=<TaskInstance: northwind.carregamento_postgres manual__2025-07-01T12:46:33.097030+00:00 [queued]>
[2025-07-01T13:16:29.517+0000] {taskinstance.py:2170} INFO - Starting attempt 2 of 2
[2025-07-01T13:16:29.543+0000] {taskinstance.py:2191} INFO - Executing <Task(DockerOperator): carregamento_postgres> on 2025-07-01 12:46:33.097030+00:00
[2025-07-01T13:16:29.566+0000] {standard_task_runner.py:60} INFO - Started process 170 to run task
[2025-07-01T13:16:29.590+0000] {standard_task_runner.py:87} INFO - Running: ['***', 'tasks', 'run', 'northwind', 'carregamento_postgres', 'manual__2025-07-01T12:46:33.097030+00:00', '--job-id', '36', '--raw', '--subdir', 'DAGS_FOLDER/dag.py', '--cfg-path', '/tmp/tmpl6g3pyp9']
[2025-07-01T13:16:29.593+0000] {standard_task_runner.py:88} INFO - Job 36: Subtask carregamento_postgres
[2025-07-01T13:16:29.773+0000] {task_command.py:423} INFO - Running <TaskInstance: northwind.carregamento_postgres manual__2025-07-01T12:46:33.097030+00:00 [running]> on host a0138d8cef03
[2025-07-01T13:16:30.006+0000] {taskinstance.py:2480} INFO - Exporting env vars: AIRFLOW_CTX_DAG_EMAIL='lrbf@cin.ufpe.br' AIRFLOW_CTX_DAG_OWNER='***' AIRFLOW_CTX_DAG_ID='northwind' AIRFLOW_CTX_TASK_ID='carregamento_postgres' AIRFLOW_CTX_EXECUTION_DATE='2025-07-01T12:46:33.097030+00:00' AIRFLOW_CTX_TRY_NUMBER='2' AIRFLOW_CTX_DAG_RUN_ID='manual__2025-07-01T12:46:33.097030+00:00'
[2025-07-01T13:16:30.405+0000] {docker.py:359} INFO - Starting docker container from image meltano:latest
[2025-07-01T13:16:31.102+0000] {docker.py:429} INFO - Running meltano install...
[2025-07-01T13:16:34.750+0000] {docker.py:429} INFO - [2m2025-07-01T13:16:34.749262Z[0m [[32m[1minfo     [0m] [1mInstalling 7 plugins          [0m
[2025-07-01T13:16:34.766+0000] {docker.py:429} INFO - [2m2025-07-01T13:16:34.765398Z[0m [[32m[1minfo     [0m] [1mInstalling extractor 'tap-postgres'[0m
[2025-07-01T13:16:34.802+0000] {docker.py:429} INFO - [2m2025-07-01T13:16:34.801541Z[0m [[32m[1minfo     [0m] [1mInstalling extractor 'tap-csv'[0m
[2025-07-01T13:16:34.839+0000] {docker.py:429} INFO - [2m2025-07-01T13:16:34.838591Z[0m [[32m[1minfo     [0m] [1mInstalling extractor 'tap-csv-latest'[0m
[2025-07-01T13:16:34.883+0000] {docker.py:429} INFO - [2m2025-07-01T13:16:34.882503Z[0m [[32m[1minfo     [0m] [1mInstalling loader 'target-postgres'[0m
[2025-07-01T13:16:34.932+0000] {docker.py:429} INFO - [2m2025-07-01T13:16:34.931215Z[0m [[32m[1minfo     [0m] [1mInstalling loader 'target-csv'[0m
[2025-07-01T13:16:34.984+0000] {docker.py:429} INFO - [2m2025-07-01T13:16:34.983024Z[0m [[32m[1minfo     [0m] [1mInstalling loader 'target-csv-postgres'[0m
[2025-07-01T13:16:35.052+0000] {docker.py:429} INFO - [2m2025-07-01T13:16:35.051285Z[0m [[32m[1minfo     [0m] [1mInstalling loader 'target-csv-csv'[0m
[2025-07-01T13:16:39.729+0000] {docker.py:429} INFO - [2m2025-07-01T13:16:39.720930Z[0m [[32m[1minfo     [0m] [1mInstalled loader 'target-postgres'[0m
[2025-07-01T13:16:40.226+0000] {docker.py:429} INFO - [2m2025-07-01T13:16:40.225167Z[0m [[32m[1minfo     [0m] [1mInstalled extractor 'tap-postgres'[0m
[2025-07-01T13:16:49.410+0000] {docker.py:429} INFO - [2m2025-07-01T13:16:49.408663Z[0m [[32m[1minfo     [0m] [1mInstalled extractor 'tap-csv-latest'[0m
[2025-07-01T13:16:49.466+0000] {docker.py:429} INFO - [2m2025-07-01T13:16:49.465149Z[0m [[32m[1minfo     [0m] [1mInstalled extractor 'tap-csv' [0m
[2025-07-01T13:16:50.234+0000] {docker.py:429} INFO - [2m2025-07-01T13:16:50.233729Z[0m [[32m[1minfo     [0m] [1mInstalled loader 'target-csv' [0m
[2025-07-01T13:16:50.332+0000] {docker.py:429} INFO - [2m2025-07-01T13:16:50.331291Z[0m [[32m[1minfo     [0m] [1mInstalled loader 'target-csv-csv'[0m
[2025-07-01T13:16:50.395+0000] {docker.py:429} INFO - [2m2025-07-01T13:16:50.394387Z[0m [[32m[1minfo     [0m] [1mInstalled loader 'target-csv-postgres'[0m
[2025-07-01T13:16:50.395+0000] {docker.py:429} INFO - [2m2025-07-01T13:16:50.395138Z[0m [[32m[1minfo     [0m] [1mInstalled 7/7 plugins         [0m
[2025-07-01T13:16:51.701+0000] {docker.py:429} INFO - Meltano install completed. Executing command: meltano el tap-csv-latest target-postgres
[2025-07-01T13:16:53.174+0000] {docker.py:429} INFO - [2m2025-07-01T13:16:53.173489Z[0m [[32m[1minfo     [0m] [1mEnvironment 'dev' is active   [0m
[2025-07-01T13:16:53.759+0000] {docker.py:429} INFO - [2m2025-07-01T13:16:53.758217Z[0m [[32m[1minfo     [0m] [1mRunning extract & load...     [0m [36mname[0m=[35mmeltano[0m [36mrun_id[0m=[35me9faf08b-9d0b-4da4-ab20-608f6ce081e9[0m [36mstate_id[0m=[35m2025-07-01T131653--tap-csv-latest--target-postgres[0m
[2025-07-01T13:17:01.886+0000] {docker.py:429} INFO - [2m2025-07-01T13:17:01.884837Z[0m [[32m[1minfo     [0m] [1mNo CSV file definitions found.[0m [36mcmd_type[0m=[35mextractor[0m [36mname[0m=[35mtap-csv-latest[0m [36mrun_id[0m=[35me9faf08b-9d0b-4da4-ab20-608f6ce081e9[0m [36mstate_id[0m=[35m2025-07-01T131653--tap-csv-latest--target-postgres[0m [36mstdio[0m=[35mstderr[0m
[2025-07-01T13:16:54.694+0000] {docker.py:429} INFO - [2m2025-07-01T13:16:54.693650Z[0m [[32m[1minfo     [0m] [1mtarget-postgres v0.4.3, Meltano SDK v0.47.4[0m [36mcmd_type[0m=[35mloader[0m [36mname[0m=[35mtarget-postgres[0m [36mrun_id[0m=[35me9faf08b-9d0b-4da4-ab20-608f6ce081e9[0m [36mstate_id[0m=[35m2025-07-01T131653--tap-csv-latest--target-postgres[0m [36mstdio[0m=[35mstderr[0m
[2025-07-01T13:16:54.696+0000] {docker.py:429} INFO - [2m2025-07-01T13:16:54.695376Z[0m [[32m[1minfo     [0m] [1m/opt/meltano/.meltano/loaders/target-postgres/venv/lib/python3.9/site-packages/singer_sdk/plugin_base.py:715: SingerSDKDeprecationWarning: Passing a list of config file paths is deprecated. Please pass the config as a dictionary instead.[0m [36mcmd_type[0m=[35mloader[0m [36mname[0m=[35mtarget-postgres[0m [36mrun_id[0m=[35me9faf08b-9d0b-4da4-ab20-608f6ce081e9[0m [36mstate_id[0m=[35m2025-07-01T131653--tap-csv-latest--target-postgres[0m [36mstdio[0m=[35mstderr[0m
[2025-07-01T13:16:54.697+0000] {docker.py:429} INFO - [2m2025-07-01T13:16:54.695858Z[0m [[32m[1minfo     [0m] [1m  super().__init__(           [0m [36mcmd_type[0m=[35mloader[0m [36mname[0m=[35mtarget-postgres[0m [36mrun_id[0m=[35me9faf08b-9d0b-4da4-ab20-608f6ce081e9[0m [36mstate_id[0m=[35m2025-07-01T131653--tap-csv-latest--target-postgres[0m [36mstdio[0m=[35mstderr[0m
[2025-07-01T13:16:54.697+0000] {docker.py:429} INFO - [2m2025-07-01T13:16:54.696289Z[0m [[32m[1minfo     [0m] [1m                              [0m [36mcmd_type[0m=[35mloader[0m [36mname[0m=[35mtarget-postgres[0m [36mrun_id[0m=[35me9faf08b-9d0b-4da4-ab20-608f6ce081e9[0m [36mstate_id[0m=[35m2025-07-01T131653--tap-csv-latest--target-postgres[0m [36mstdio[0m=[35mstderr[0m
[2025-07-01T13:16:54.698+0000] {docker.py:429} INFO - [2m2025-07-01T13:16:54.696683Z[0m [[32m[1minfo     [0m] [1mSkipping parse of env var settings...[0m [36mcmd_type[0m=[35mloader[0m [36mname[0m=[35mtarget-postgres[0m [36mrun_id[0m=[35me9faf08b-9d0b-4da4-ab20-608f6ce081e9[0m [36mstate_id[0m=[35m2025-07-01T131653--tap-csv-latest--target-postgres[0m [36mstdio[0m=[35mstderr[0m
[2025-07-01T13:16:54.698+0000] {docker.py:429} INFO - [2m2025-07-01T13:16:54.697289Z[0m [[32m[1minfo     [0m] [1mThe `dialect+driver` configuration option is deprecated. Please set it to `postgresql+psycopg`, as this will be the hard-coded value in the future.[0m [36mcmd_type[0m=[35mloader[0m [36mname[0m=[35mtarget-postgres[0m [36mrun_id[0m=[35me9faf08b-9d0b-4da4-ab20-608f6ce081e9[0m [36mstate_id[0m=[35m2025-07-01T131653--tap-csv-latest--target-postgres[0m [36mstdio[0m=[35mstderr[0m
[2025-07-01T13:16:54.699+0000] {docker.py:429} INFO - [2m2025-07-01T13:16:54.697744Z[0m [[32m[1minfo     [0m] [1mReader 'target-postgres' completed processing 0 lines of input (0 schemas, 0 records, 0 batch manifests, 0 state messages, 0 activate version messages).[0m [36mcmd_type[0m=[35mloader[0m [36mname[0m=[35mtarget-postgres[0m [36mrun_id[0m=[35me9faf08b-9d0b-4da4-ab20-608f6ce081e9[0m [36mstate_id[0m=[35m2025-07-01T131653--tap-csv-latest--target-postgres[0m [36mstdio[0m=[35mstderr[0m
[2025-07-01T13:16:54.861+0000] {docker.py:429} INFO - [2m2025-07-01T13:16:54.859936Z[0m [[31m[1merror    [0m] [1mExtraction failed             [0m [36mcode[0m=[35m1[0m [36mmessage[0m=[35m'No CSV file definitions found.'[0m [36mname[0m=[35mmeltano[0m [36mrun_id[0m=[35me9faf08b-9d0b-4da4-ab20-608f6ce081e9[0m [36mstate_id[0m=[35m2025-07-01T131653--tap-csv-latest--target-postgres[0m
[2025-07-01T13:16:54.861+0000] {docker.py:429} INFO - [2m2025-07-01T13:16:54.860817Z[0m [[32m[1minfo     [0m] [1mELT could not be completed: Extractor failed.[0m [36mcmd_type[0m=[35melt[0m [36mname[0m=[35mmeltano[0m [36mrun_id[0m=[35me9faf08b-9d0b-4da4-ab20-608f6ce081e9[0m [36mstate_id[0m=[35m2025-07-01T131653--tap-csv-latest--target-postgres[0m [36mstdio[0m=[35mstderr[0m
[2025-07-01T13:16:54.862+0000] {docker.py:429} INFO - [2m2025-07-01T13:16:54.861137Z[0m [[32m[1minfo     [0m] [1mFor more detailed log messages re-run the command using 'meltano --log-level=debug ...' CLI flag.[0m [36mcmd_type[0m=[35melt[0m [36mname[0m=[35mmeltano[0m [36mrun_id[0m=[35me9faf08b-9d0b-4da4-ab20-608f6ce081e9[0m [36mstate_id[0m=[35m2025-07-01T131653--tap-csv-latest--target-postgres[0m [36mstdio[0m=[35mstderr[0m
[2025-07-01T13:16:54.862+0000] {docker.py:429} INFO - [2m2025-07-01T13:16:54.861406Z[0m [[32m[1minfo     [0m] [1mNote that you can also check the generated log file at '/opt/meltano/.meltano/logs/elt/2025-07-01T131653--tap-csv-latest--target-postgres/e9faf08b-9d0b-4da4-ab20-608f6ce081e9/elt.log'.[0m [36mcmd_type[0m=[35melt[0m [36mname[0m=[35mmeltano[0m [36mrun_id[0m=[35me9faf08b-9d0b-4da4-ab20-608f6ce081e9[0m [36mstate_id[0m=[35m2025-07-01T131653--tap-csv-latest--target-postgres[0m [36mstdio[0m=[35mstderr[0m
[2025-07-01T13:16:54.862+0000] {docker.py:429} INFO - [2m2025-07-01T13:16:54.861681Z[0m [[32m[1minfo     [0m] [1mFor more information on debugging and logging: https://docs.meltano.com/reference/command-line-interface#debugging[0m [36mcmd_type[0m=[35melt[0m [36mname[0m=[35mmeltano[0m [36mrun_id[0m=[35me9faf08b-9d0b-4da4-ab20-608f6ce081e9[0m [36mstate_id[0m=[35m2025-07-01T131653--tap-csv-latest--target-postgres[0m [36mstdio[0m=[35mstderr[0m
[2025-07-01T13:16:54.881+0000] {docker.py:429} INFO - Need help fixing this problem? Visit http://melta.no/ for troubleshooting steps, or to
join our friendly Slack community.

ELT could not be completed: Extractor failed.
For more detailed log messages re-run the command using 'meltano --log-level=debug ...' CLI flag.
Note that you can also check the generated log file at '/opt/meltano/.meltano/logs/elt/2025-07-01T131653--tap-csv-latest--target-postgres/e9faf08b-9d0b-4da4-ab20-608f6ce081e9/elt.log'.
For more information on debugging and logging: https://docs.meltano.com/reference/command-line-interface#debugging
[2025-07-01T13:16:56.185+0000] {taskinstance.py:2698} ERROR - Task failed with exception
Traceback (most recent call last):
  File "/home/airflow/.local/lib/python3.10/site-packages/airflow/models/taskinstance.py", line 433, in _execute_task
    result = execute_callable(context=context, **execute_callable_kwargs)
  File "/home/airflow/.local/lib/python3.10/site-packages/airflow/providers/docker/operators/docker.py", line 502, in execute
    return self._run_image()
  File "/home/airflow/.local/lib/python3.10/site-packages/airflow/providers/docker/operators/docker.py", line 376, in _run_image
    return self._run_image_with_mounts(self.mounts, add_tmp_variable=False)
  File "/home/airflow/.local/lib/python3.10/site-packages/airflow/providers/docker/operators/docker.py", line 437, in _run_image_with_mounts
    raise DockerContainerFailedException(f"Docker container failed: {result!r}", logs=log_lines)
airflow.providers.docker.exceptions.DockerContainerFailedException: Docker container failed: {'StatusCode': 1}
[2025-07-01T13:16:56.195+0000] {taskinstance.py:1138} INFO - Marking task as FAILED. dag_id=northwind, task_id=carregamento_postgres, execution_date=20250701T124633, start_date=20250701T131629, end_date=20250701T131656
[2025-07-01T13:16:56.263+0000] {logging_mixin.py:188} WARNING - /home/***/.local/lib/python3.10/site-packages/***/utils/email.py:154 RemovedInAirflow3Warning: Fetching SMTP credentials from configuration variables will be deprecated in a future release. Please set credentials using a connection instead.
[2025-07-01T13:16:56.264+0000] {configuration.py:1046} WARNING - section/key [smtp/smtp_user] not found in config
[2025-07-01T13:16:56.265+0000] {email.py:270} INFO - Email alerting: attempt 1
[2025-07-01T13:16:56.276+0000] {configuration.py:1046} WARNING - section/key [smtp/smtp_user] not found in config
[2025-07-01T13:16:56.277+0000] {email.py:270} INFO - Email alerting: attempt 1
[2025-07-01T13:16:56.277+0000] {taskinstance.py:826} ERROR - Failed to send email to: ['lrbf@cin.ufpe.br']
Traceback (most recent call last):
  File "/home/airflow/.local/lib/python3.10/site-packages/airflow/models/taskinstance.py", line 2334, in _run_raw_task
    self._execute_task_with_callbacks(context, test_mode, session=session)
  File "/home/airflow/.local/lib/python3.10/site-packages/airflow/models/taskinstance.py", line 2499, in _execute_task_with_callbacks
    result = self._execute_task(context, task_orig)
  File "/home/airflow/.local/lib/python3.10/site-packages/airflow/models/taskinstance.py", line 2516, in _execute_task
    return _execute_task(self, context, task_orig)
  File "/home/airflow/.local/lib/python3.10/site-packages/airflow/models/taskinstance.py", line 433, in _execute_task
    result = execute_callable(context=context, **execute_callable_kwargs)
  File "/home/airflow/.local/lib/python3.10/site-packages/airflow/providers/docker/operators/docker.py", line 502, in execute
    return self._run_image()
  File "/home/airflow/.local/lib/python3.10/site-packages/airflow/providers/docker/operators/docker.py", line 376, in _run_image
    return self._run_image_with_mounts(self.mounts, add_tmp_variable=False)
  File "/home/airflow/.local/lib/python3.10/site-packages/airflow/providers/docker/operators/docker.py", line 437, in _run_image_with_mounts
    raise DockerContainerFailedException(f"Docker container failed: {result!r}", logs=log_lines)
airflow.providers.docker.exceptions.DockerContainerFailedException: Docker container failed: {'StatusCode': 1}

During handling of the above exception, another exception occurred:

Traceback (most recent call last):
  File "/home/airflow/.local/lib/python3.10/site-packages/airflow/models/taskinstance.py", line 1000, in _email_alert
    send_email(task.email, subject, html_content)
  File "/home/airflow/.local/lib/python3.10/site-packages/airflow/utils/email.py", line 80, in send_email
    return backend(
  File "/home/airflow/.local/lib/python3.10/site-packages/airflow/utils/email.py", line 154, in send_email_smtp
    send_mime_email(e_from=mail_from, e_to=recipients, mime_msg=msg, conn_id=conn_id, dryrun=dryrun)
  File "/home/airflow/.local/lib/python3.10/site-packages/airflow/utils/email.py", line 272, in send_mime_email
    smtp_conn = _get_smtp_connection(smtp_host, smtp_port, smtp_timeout, smtp_ssl)
  File "/home/airflow/.local/lib/python3.10/site-packages/airflow/utils/email.py", line 316, in _get_smtp_connection
    return smtplib.SMTP(host=host, port=port, timeout=timeout)
  File "/usr/local/lib/python3.10/smtplib.py", line 255, in __init__
    (code, msg) = self.connect(host, port)
  File "/usr/local/lib/python3.10/smtplib.py", line 341, in connect
    self.sock = self._get_socket(host, port, self.timeout)
  File "/usr/local/lib/python3.10/smtplib.py", line 312, in _get_socket
    return socket.create_connection((host, port), timeout,
  File "/usr/local/lib/python3.10/socket.py", line 845, in create_connection
    raise err
  File "/usr/local/lib/python3.10/socket.py", line 833, in create_connection
    sock.connect(sa)
ConnectionRefusedError: [Errno 111] Connection refused

During handling of the above exception, another exception occurred:

Traceback (most recent call last):
  File "/home/airflow/.local/lib/python3.10/site-packages/airflow/models/taskinstance.py", line 824, in _handle_failure
    task_instance.email_alert(error, failure_context["task"])
  File "/home/airflow/.local/lib/python3.10/site-packages/airflow/models/taskinstance.py", line 2946, in email_alert
    _email_alert(task_instance=self, exception=exception, task=task)
  File "/home/airflow/.local/lib/python3.10/site-packages/airflow/models/taskinstance.py", line 1002, in _email_alert
    send_email(task.email, subject, html_content_err)
  File "/home/airflow/.local/lib/python3.10/site-packages/airflow/utils/email.py", line 80, in send_email
    return backend(
  File "/home/airflow/.local/lib/python3.10/site-packages/airflow/utils/email.py", line 154, in send_email_smtp
    send_mime_email(e_from=mail_from, e_to=recipients, mime_msg=msg, conn_id=conn_id, dryrun=dryrun)
  File "/home/airflow/.local/lib/python3.10/site-packages/airflow/utils/email.py", line 272, in send_mime_email
    smtp_conn = _get_smtp_connection(smtp_host, smtp_port, smtp_timeout, smtp_ssl)
  File "/home/airflow/.local/lib/python3.10/site-packages/airflow/utils/email.py", line 316, in _get_smtp_connection
    return smtplib.SMTP(host=host, port=port, timeout=timeout)
  File "/usr/local/lib/python3.10/smtplib.py", line 255, in __init__
    (code, msg) = self.connect(host, port)
  File "/usr/local/lib/python3.10/smtplib.py", line 341, in connect
    self.sock = self._get_socket(host, port, self.timeout)
  File "/usr/local/lib/python3.10/smtplib.py", line 312, in _get_socket
    return socket.create_connection((host, port), timeout,
  File "/usr/local/lib/python3.10/socket.py", line 845, in create_connection
    raise err
  File "/usr/local/lib/python3.10/socket.py", line 833, in create_connection
    sock.connect(sa)
ConnectionRefusedError: [Errno 111] Connection refused
[2025-07-01T13:16:56.307+0000] {standard_task_runner.py:107} ERROR - Failed to execute job 36 for task carregamento_postgres (Docker container failed: {'StatusCode': 1}; 170)
[2025-07-01T13:16:56.339+0000] {local_task_job_runner.py:234} INFO - Task exited with return code 1
[2025-07-01T13:16:56.367+0000] {taskinstance.py:3280} INFO - 0 downstream tasks scheduled from follow-on schedule check
