[2025-06-26T18:02:16.058+0000] {taskinstance.py:1956} INFO - Dependencies all met for dep_context=non-requeueable deps ti=<TaskInstance: northwind.carregamento_postgres manual__2025-06-26T18:00:27.253055+00:00 [queued]>
[2025-06-26T18:02:16.069+0000] {taskinstance.py:1956} INFO - Dependencies all met for dep_context=requeueable deps ti=<TaskInstance: northwind.carregamento_postgres manual__2025-06-26T18:00:27.253055+00:00 [queued]>
[2025-06-26T18:02:16.069+0000] {taskinstance.py:2170} INFO - Starting attempt 1 of 2
[2025-06-26T18:02:16.086+0000] {taskinstance.py:2191} INFO - Executing <Task(DockerOperator): carregamento_postgres> on 2025-06-26 18:00:27.253055+00:00
[2025-06-26T18:02:16.093+0000] {standard_task_runner.py:60} INFO - Started process 234 to run task
[2025-06-26T18:02:16.097+0000] {standard_task_runner.py:87} INFO - Running: ['***', 'tasks', 'run', 'northwind', 'carregamento_postgres', 'manual__2025-06-26T18:00:27.253055+00:00', '--job-id', '324', '--raw', '--subdir', 'DAGS_FOLDER/dag.py', '--cfg-path', '/tmp/tmpp60vglwu']
[2025-06-26T18:02:16.101+0000] {standard_task_runner.py:88} INFO - Job 324: Subtask carregamento_postgres
[2025-06-26T18:02:16.151+0000] {task_command.py:423} INFO - Running <TaskInstance: northwind.carregamento_postgres manual__2025-06-26T18:00:27.253055+00:00 [running]> on host 6afc1f3750fb
[2025-06-26T18:02:16.211+0000] {abstractoperator.py:707} ERROR - Exception rendering Jinja template for task 'carregamento_postgres', field 'command'. Template: ['bash', '/opt/meltano/scripts/load_meltano.sh', '{{ task_instance.xcom_pull(task_ids=\'gerar_config_csv_dinamica\') | tojson | replace(\'"\', \'\\"\') }}', '{{ task_instance.xcom_pull(task_ids=\'gerar_config_target_postgres_dinamica\') | tojson | replace(\'"\', \'\\"\') }}']
Traceback (most recent call last):
  File "/home/airflow/.local/lib/python3.10/site-packages/airflow/models/abstractoperator.py", line 699, in _do_render_template_fields
    rendered_content = self.render_template(
  File "/home/airflow/.local/lib/python3.10/site-packages/airflow/template/templater.py", line 184, in render_template
    return [self.render_template(element, context, jinja_env, oids) for element in value]
  File "/home/airflow/.local/lib/python3.10/site-packages/airflow/template/templater.py", line 184, in <listcomp>
    return [self.render_template(element, context, jinja_env, oids) for element in value]
  File "/home/airflow/.local/lib/python3.10/site-packages/airflow/template/templater.py", line 171, in render_template
    template = jinja_env.get_template(value)
  File "/home/airflow/.local/lib/python3.10/site-packages/jinja2/environment.py", line 1010, in get_template
    return self._load_template(name, globals)
  File "/home/airflow/.local/lib/python3.10/site-packages/jinja2/environment.py", line 969, in _load_template
    template = self.loader.load(self, name, self.make_globals(globals))
  File "/home/airflow/.local/lib/python3.10/site-packages/jinja2/loaders.py", line 125, in load
    source, filename, uptodate = self.get_source(environment, name)
  File "/home/airflow/.local/lib/python3.10/site-packages/jinja2/loaders.py", line 204, in get_source
    raise TemplateNotFound(template)
jinja2.exceptions.TemplateNotFound: /opt/meltano/scripts/load_meltano.sh
[2025-06-26T18:02:16.215+0000] {taskinstance.py:2698} ERROR - Task failed with exception
Traceback (most recent call last):
  File "/home/airflow/.local/lib/python3.10/site-packages/airflow/models/taskinstance.py", line 2334, in _run_raw_task
    self._execute_task_with_callbacks(context, test_mode, session=session)
  File "/home/airflow/.local/lib/python3.10/site-packages/airflow/models/taskinstance.py", line 2465, in _execute_task_with_callbacks
    task_orig = self.render_templates(context=context)
  File "/home/airflow/.local/lib/python3.10/site-packages/airflow/models/taskinstance.py", line 2877, in render_templates
    original_task.render_template_fields(context)
  File "/home/airflow/.local/lib/python3.10/site-packages/airflow/models/baseoperator.py", line 1241, in render_template_fields
    self._do_render_template_fields(self, self.template_fields, context, jinja_env, set())
  File "/home/airflow/.local/lib/python3.10/site-packages/airflow/utils/session.py", line 79, in wrapper
    return func(*args, session=session, **kwargs)
  File "/home/airflow/.local/lib/python3.10/site-packages/airflow/models/abstractoperator.py", line 699, in _do_render_template_fields
    rendered_content = self.render_template(
  File "/home/airflow/.local/lib/python3.10/site-packages/airflow/template/templater.py", line 184, in render_template
    return [self.render_template(element, context, jinja_env, oids) for element in value]
  File "/home/airflow/.local/lib/python3.10/site-packages/airflow/template/templater.py", line 184, in <listcomp>
    return [self.render_template(element, context, jinja_env, oids) for element in value]
  File "/home/airflow/.local/lib/python3.10/site-packages/airflow/template/templater.py", line 171, in render_template
    template = jinja_env.get_template(value)
  File "/home/airflow/.local/lib/python3.10/site-packages/jinja2/environment.py", line 1010, in get_template
    return self._load_template(name, globals)
  File "/home/airflow/.local/lib/python3.10/site-packages/jinja2/environment.py", line 969, in _load_template
    template = self.loader.load(self, name, self.make_globals(globals))
  File "/home/airflow/.local/lib/python3.10/site-packages/jinja2/loaders.py", line 125, in load
    source, filename, uptodate = self.get_source(environment, name)
  File "/home/airflow/.local/lib/python3.10/site-packages/jinja2/loaders.py", line 204, in get_source
    raise TemplateNotFound(template)
jinja2.exceptions.TemplateNotFound: /opt/meltano/scripts/load_meltano.sh
[2025-06-26T18:02:16.232+0000] {taskinstance.py:1138} INFO - Marking task as UP_FOR_RETRY. dag_id=northwind, task_id=carregamento_postgres, execution_date=20250626T180027, start_date=20250626T180216, end_date=20250626T180216
[2025-06-26T18:02:16.253+0000] {standard_task_runner.py:107} ERROR - Failed to execute job 324 for task carregamento_postgres (/opt/meltano/scripts/load_meltano.sh; 234)
[2025-06-26T18:02:16.274+0000] {local_task_job_runner.py:234} INFO - Task exited with return code 1
[2025-06-26T18:02:16.296+0000] {taskinstance.py:3280} INFO - 0 downstream tasks scheduled from follow-on schedule check
