[2025-06-27T21:06:31.519+0000] {taskinstance.py:1956} INFO - Dependencies all met for dep_context=non-requeueable deps ti=<TaskInstance: northwind.extração_postgres manual__2025-06-27T21:06:29.987477+00:00 [queued]>
[2025-06-27T21:06:31.533+0000] {taskinstance.py:1956} INFO - Dependencies all met for dep_context=requeueable deps ti=<TaskInstance: northwind.extração_postgres manual__2025-06-27T21:06:29.987477+00:00 [queued]>
[2025-06-27T21:06:31.533+0000] {taskinstance.py:2170} INFO - Starting attempt 1 of 2
[2025-06-27T21:06:31.548+0000] {taskinstance.py:2191} INFO - Executing <Task(DockerOperator): extração_postgres> on 2025-06-27 21:06:29.987477+00:00
[2025-06-27T21:06:31.553+0000] {standard_task_runner.py:60} INFO - Started process 175 to run task
[2025-06-27T21:06:31.556+0000] {standard_task_runner.py:87} INFO - Running: ['***', 'tasks', 'run', 'northwind', 'extração_postgres', 'manual__2025-06-27T21:06:29.987477+00:00', '--job-id', '2', '--raw', '--subdir', 'DAGS_FOLDER/dag.py', '--cfg-path', '/tmp/tmper1rcfv6']
[2025-06-27T21:06:31.560+0000] {standard_task_runner.py:88} INFO - Job 2: Subtask extração_postgres
[2025-06-27T21:06:31.631+0000] {task_command.py:423} INFO - Running <TaskInstance: northwind.extração_postgres manual__2025-06-27T21:06:29.987477+00:00 [running]> on host 4e070cd4d905
[2025-06-27T21:06:31.803+0000] {taskinstance.py:2480} INFO - Exporting env vars: AIRFLOW_CTX_DAG_EMAIL='lrbf@cin.ufpe.br' AIRFLOW_CTX_DAG_OWNER='***' AIRFLOW_CTX_DAG_ID='northwind' AIRFLOW_CTX_TASK_ID='extração_postgres' AIRFLOW_CTX_EXECUTION_DATE='2025-06-27T21:06:29.987477+00:00' AIRFLOW_CTX_TRY_NUMBER='1' AIRFLOW_CTX_DAG_RUN_ID='manual__2025-06-27T21:06:29.987477+00:00'
[2025-06-27T21:06:31.964+0000] {docker.py:359} INFO - Starting docker container from image meltano:latest
[2025-06-27T21:06:31.971+0000] {taskinstance.py:2698} ERROR - Task failed with exception
Traceback (most recent call last):
  File "/home/airflow/.local/lib/python3.10/site-packages/docker/api/client.py", line 265, in _raise_for_status
    response.raise_for_status()
  File "/home/airflow/.local/lib/python3.10/site-packages/requests/models.py", line 1021, in raise_for_status
    raise HTTPError(http_error_msg, response=self)
requests.exceptions.HTTPError: 400 Client Error: Bad Request for url: http+docker://localhost/v1.47/containers/create

The above exception was the direct cause of the following exception:

Traceback (most recent call last):
  File "/home/airflow/.local/lib/python3.10/site-packages/airflow/models/taskinstance.py", line 433, in _execute_task
    result = execute_callable(context=context, **execute_callable_kwargs)
  File "/home/airflow/.local/lib/python3.10/site-packages/airflow/providers/docker/operators/docker.py", line 502, in execute
    return self._run_image()
  File "/home/airflow/.local/lib/python3.10/site-packages/airflow/providers/docker/operators/docker.py", line 376, in _run_image
    return self._run_image_with_mounts(self.mounts, add_tmp_variable=False)
  File "/home/airflow/.local/lib/python3.10/site-packages/airflow/providers/docker/operators/docker.py", line 391, in _run_image_with_mounts
    self.container = self.cli.create_container(
  File "/home/airflow/.local/lib/python3.10/site-packages/docker/api/container.py", line 439, in create_container
    return self.create_container_from_config(config, name, platform)
  File "/home/airflow/.local/lib/python3.10/site-packages/docker/api/container.py", line 456, in create_container_from_config
    return self._result(res, True)
  File "/home/airflow/.local/lib/python3.10/site-packages/docker/api/client.py", line 271, in _result
    self._raise_for_status(response)
  File "/home/airflow/.local/lib/python3.10/site-packages/docker/api/client.py", line 267, in _raise_for_status
    raise create_api_error_from_http_exception(e) from e
  File "/home/airflow/.local/lib/python3.10/site-packages/docker/errors.py", line 39, in create_api_error_from_http_exception
    raise cls(e, response=response, explanation=explanation) from e
docker.errors.APIError: 400 Client Error for http+docker://localhost/v1.47/containers/create: Bad Request ("invalid mount config for type "bind": bind source path does not exist: /opt/meltano")
[2025-06-27T21:06:31.990+0000] {taskinstance.py:1138} INFO - Marking task as UP_FOR_RETRY. dag_id=northwind, task_id=extração_postgres, execution_date=20250627T210629, start_date=20250627T210631, end_date=20250627T210631
[2025-06-27T21:06:32.006+0000] {standard_task_runner.py:107} ERROR - Failed to execute job 2 for task extração_postgres (400 Client Error for http+docker://localhost/v1.47/containers/create: Bad Request ("invalid mount config for type "bind": bind source path does not exist: /opt/meltano"); 175)
[2025-06-27T21:06:32.018+0000] {local_task_job_runner.py:234} INFO - Task exited with return code 1
[2025-06-27T21:06:32.043+0000] {taskinstance.py:3280} INFO - 0 downstream tasks scheduled from follow-on schedule check
