[2025-06-24T18:09:07.326+0000] {taskinstance.py:1956} INFO - Dependencies all met for dep_context=non-requeueable deps ti=<TaskInstance: northwind.extração_postgres manual__2025-06-24T18:09:05.180948+00:00 [queued]>
[2025-06-24T18:09:07.348+0000] {taskinstance.py:1956} INFO - Dependencies all met for dep_context=requeueable deps ti=<TaskInstance: northwind.extração_postgres manual__2025-06-24T18:09:05.180948+00:00 [queued]>
[2025-06-24T18:09:07.348+0000] {taskinstance.py:2170} INFO - Starting attempt 1 of 2
[2025-06-24T18:09:07.390+0000] {taskinstance.py:2191} INFO - Executing <Task(DockerOperator): extração_postgres> on 2025-06-24 18:09:05.180948+00:00
[2025-06-24T18:09:07.403+0000] {standard_task_runner.py:60} INFO - Started process 237 to run task
[2025-06-24T18:09:07.419+0000] {standard_task_runner.py:87} INFO - Running: ['***', 'tasks', 'run', 'northwind', 'extração_postgres', 'manual__2025-06-24T18:09:05.180948+00:00', '--job-id', '52', '--raw', '--subdir', 'DAGS_FOLDER/dag.py', '--cfg-path', '/tmp/tmppwfbp_73']
[2025-06-24T18:09:07.422+0000] {standard_task_runner.py:88} INFO - Job 52: Subtask extração_postgres
[2025-06-24T18:09:07.505+0000] {task_command.py:423} INFO - Running <TaskInstance: northwind.extração_postgres manual__2025-06-24T18:09:05.180948+00:00 [running]> on host a06304be4538
[2025-06-24T18:09:07.734+0000] {taskinstance.py:2480} INFO - Exporting env vars: AIRFLOW_CTX_DAG_EMAIL='lrbf@cin.ufpe.br' AIRFLOW_CTX_DAG_OWNER='***' AIRFLOW_CTX_DAG_ID='northwind' AIRFLOW_CTX_TASK_ID='extração_postgres' AIRFLOW_CTX_EXECUTION_DATE='2025-06-24T18:09:05.180948+00:00' AIRFLOW_CTX_TRY_NUMBER='1' AIRFLOW_CTX_DAG_RUN_ID='manual__2025-06-24T18:09:05.180948+00:00'
[2025-06-24T18:09:08.247+0000] {docker.py:486} INFO - Pulling docker image meltano
[2025-06-24T18:09:10.551+0000] {taskinstance.py:2698} ERROR - Task failed with exception
Traceback (most recent call last):
  File "/home/airflow/.local/lib/python3.10/site-packages/docker/api/client.py", line 265, in _raise_for_status
    response.raise_for_status()
  File "/home/airflow/.local/lib/python3.10/site-packages/requests/models.py", line 1021, in raise_for_status
    raise HTTPError(http_error_msg, response=self)
requests.exceptions.HTTPError: 404 Client Error: Not Found for url: http+docker://localhost/v1.47/images/create?tag=latest&fromImage=meltano

The above exception was the direct cause of the following exception:

Traceback (most recent call last):
  File "/home/airflow/.local/lib/python3.10/site-packages/airflow/models/taskinstance.py", line 433, in _execute_task
    result = execute_callable(context=context, **execute_callable_kwargs)
  File "/home/airflow/.local/lib/python3.10/site-packages/airflow/providers/docker/operators/docker.py", line 488, in execute
    for output in self.cli.pull(self.image, stream=True, decode=True):
  File "/home/airflow/.local/lib/python3.10/site-packages/docker/api/image.py", line 429, in pull
    self._raise_for_status(response)
  File "/home/airflow/.local/lib/python3.10/site-packages/docker/api/client.py", line 267, in _raise_for_status
    raise create_api_error_from_http_exception(e) from e
  File "/home/airflow/.local/lib/python3.10/site-packages/docker/errors.py", line 39, in create_api_error_from_http_exception
    raise cls(e, response=response, explanation=explanation) from e
docker.errors.ImageNotFound: 404 Client Error for http+docker://localhost/v1.47/images/create?tag=latest&fromImage=meltano: Not Found ("pull access denied for meltano, repository does not exist or may require 'docker login': denied: requested access to the resource is denied")
[2025-06-24T18:09:10.561+0000] {taskinstance.py:1138} INFO - Marking task as UP_FOR_RETRY. dag_id=northwind, task_id=extração_postgres, execution_date=20250624T180905, start_date=20250624T180907, end_date=20250624T180910
[2025-06-24T18:09:10.600+0000] {standard_task_runner.py:107} ERROR - Failed to execute job 52 for task extração_postgres (404 Client Error for http+docker://localhost/v1.47/images/create?tag=latest&fromImage=meltano: Not Found ("pull access denied for meltano, repository does not exist or may require 'docker login': denied: requested access to the resource is denied"); 237)
[2025-06-24T18:09:10.628+0000] {local_task_job_runner.py:234} INFO - Task exited with return code 1
[2025-06-24T18:09:10.655+0000] {taskinstance.py:3280} INFO - 0 downstream tasks scheduled from follow-on schedule check
