[2025-06-17T15:01:13.393+0000] {taskinstance.py:1956} INFO - Dependencies all met for dep_context=non-requeueable deps ti=<TaskInstance: northwind.extra√ß√£o_postgres manual__2025-06-17T15:01:11.513975+00:00 [queued]>
[2025-06-17T15:01:13.410+0000] {taskinstance.py:1956} INFO - Dependencies all met for dep_context=requeueable deps ti=<TaskInstance: northwind.extra√ß√£o_postgres manual__2025-06-17T15:01:11.513975+00:00 [queued]>
[2025-06-17T15:01:13.410+0000] {taskinstance.py:2170} INFO - Starting attempt 1 of 2
[2025-06-17T15:01:13.430+0000] {taskinstance.py:2191} INFO - Executing <Task(DockerOperator): extra√ß√£o_postgres> on 2025-06-17 15:01:11.513975+00:00
[2025-06-17T15:01:13.438+0000] {standard_task_runner.py:60} INFO - Started process 172 to run task
[2025-06-17T15:01:13.448+0000] {standard_task_runner.py:87} INFO - Running: ['***', 'tasks', 'run', 'northwind', 'extra√ß√£o_postgres', 'manual__2025-06-17T15:01:11.513975+00:00', '--job-id', '8', '--raw', '--subdir', 'DAGS_FOLDER/dag.py', '--cfg-path', '/tmp/tmpa2g6ccav']
[2025-06-17T15:01:13.459+0000] {standard_task_runner.py:88} INFO - Job 8: Subtask extra√ß√£o_postgres
[2025-06-17T15:01:13.572+0000] {task_command.py:423} INFO - Running <TaskInstance: northwind.extra√ß√£o_postgres manual__2025-06-17T15:01:11.513975+00:00 [running]> on host cbdfef5793b2
[2025-06-17T15:01:13.706+0000] {taskinstance.py:2480} INFO - Exporting env vars: AIRFLOW_CTX_DAG_EMAIL='lrbf@cin.ufpe.br' AIRFLOW_CTX_DAG_OWNER='***' AIRFLOW_CTX_DAG_ID='northwind' AIRFLOW_CTX_TASK_ID='extra√ß√£o_postgres' AIRFLOW_CTX_EXECUTION_DATE='2025-06-17T15:01:11.513975+00:00' AIRFLOW_CTX_TRY_NUMBER='1' AIRFLOW_CTX_DAG_RUN_ID='manual__2025-06-17T15:01:11.513975+00:00'
[2025-06-17T15:01:13.766+0000] {docker.py:359} INFO - Starting docker container from image indicium_pipeline-meltano:latest
[2025-06-17T15:01:15.813+0000] {docker.py:429} INFO - [2m2025-06-17T15:01:15.811695Z[0m [[32m[1minfo     [0m] [1mEnvironment 'dev' is active   [0m
[2025-06-17T15:01:16.080+0000] {docker.py:429} INFO - [2m2025-06-17T15:01:16.079658Z[0m [[33m[1mwarning  [0m] [1mThe `elt` command is deprecated in favor of `el`[0m
[2025-06-17T15:01:16.466+0000] {docker.py:429} INFO - [2m2025-06-17T15:01:16.465339Z[0m [[32m[1minfo     [0m] [1mRunning extract & load...     [0m [36mname[0m=[35mmeltano[0m [36mrun_id[0m=[35m82a8657f-d43d-449f-8f27-47e725696ab0[0m [36mstate_id[0m=[35m2025-06-17T150116--tap-postgres--target-csv-postgres[0m
[2025-06-17T15:01:16.680+0000] {docker.py:429} INFO - [2m2025-06-17T15:01:16.679638Z[0m [[32m[1minfo     [0m] [1mUsing systemdb state backend  [0m
[2025-06-17T15:01:16.682+0000] {docker.py:429} INFO - [2m2025-06-17T15:01:16.681486Z[0m [[33m[1mwarning  [0m] [1mNo state was found, complete import.[0m
[2025-06-17T15:01:16.689+0000] {docker.py:429} INFO - [2m2025-06-17T15:01:16.688369Z[0m [[32m[1minfo     [0m] [1mUsing custom catalog in /opt/meltano/catalog_discovery.json[0m
[2025-06-17T15:01:16.704+0000] {docker.py:429} INFO - [2m2025-06-17T15:01:16.703654Z[0m [[32m[1minfo     [0m] [1mELT could not be completed: Cannot start extractor: Executable 'tap-postgres' could not be found. Extractor 'tap-postgres' may not have been installed yet using `meltano install extractor tap-postgres`, or the executable name may be incorrect..[0m [36mcmd_type[0m=[35melt[0m [36mname[0m=[35mmeltano[0m [36mrun_id[0m=[35m82a8657f-d43d-449f-8f27-47e725696ab0[0m [36mstate_id[0m=[35m2025-06-17T150116--tap-postgres--target-csv-postgres[0m [36mstdio[0m=[35mstderr[0m
[2m2025-06-17T15:01:16.703923Z[0m [[32m[1minfo     [0m] [1mFor more detailed log messages re-run the command using 'meltano --log-level=debug ...' CLI flag.[0m [36mcmd_type[0m=[35melt[0m [36mname[0m=[35mmeltano[0m [36mrun_id[0m=[35m82a8657f-d43d-449f-8f27-47e725696ab0[0m [36mstate_id[0m=[35m2025-06-17T150116--tap-postgres--target-csv-postgres[0m [36mstdio[0m=[35mstderr[0m
[2025-06-17T15:01:16.704+0000] {docker.py:429} INFO - [2m2025-06-17T15:01:16.704084Z[0m [[32m[1minfo     [0m] [1mNote that you can also check the generated log file at '/opt/meltano/.meltano/logs/elt/2025-06-17T150116--tap-postgres--target-csv-postgres/82a8657f-d43d-449f-8f27-47e725696ab0/elt.log'.[0m [36mcmd_type[0m=[35melt[0m [36mname[0m=[35mmeltano[0m [36mrun_id[0m=[35m82a8657f-d43d-449f-8f27-47e725696ab0[0m [36mstate_id[0m=[35m2025-06-17T150116--tap-postgres--target-csv-postgres[0m [36mstdio[0m=[35mstderr[0m
[2025-06-17T15:01:16.705+0000] {docker.py:429} INFO - [2m2025-06-17T15:01:16.704261Z[0m [[32m[1minfo     [0m] [1mFor more information on debugging and logging: https://docs.meltano.com/reference/command-line-interface#debugging[0m [36mcmd_type[0m=[35melt[0m [36mname[0m=[35mmeltano[0m [36mrun_id[0m=[35m82a8657f-d43d-449f-8f27-47e725696ab0[0m [36mstate_id[0m=[35m2025-06-17T150116--tap-postgres--target-csv-postgres[0m [36mstdio[0m=[35mstderr[0m
[2025-06-17T15:01:16.713+0000] {docker.py:429} INFO - Need help fixing this problem? Visit http://melta.no/ for troubleshooting steps, or to
join our friendly Slack community.

ELT could not be completed: Cannot start extractor: Executable 'tap-postgres' could not be found. Extractor 'tap-postgres' may not have been installed yet using `meltano install extractor tap-postgres`, or the executable name may be incorrect..
For more detailed log messages re-run the command using 'meltano --log-level=debug ...' CLI flag.
Note that you can also check the generated log file at '/opt/meltano/.meltano/logs/elt/2025-06-17T150116--tap-postgres--target-csv-postgres/82a8657f-d43d-449f-8f27-47e725696ab0/elt.log'.
For more information on debugging and logging: https://docs.meltano.com/reference/command-line-interface#debugging
[2025-06-17T15:01:18.225+0000] {taskinstance.py:2698} ERROR - Task failed with exception
Traceback (most recent call last):
  File "/home/airflow/.local/lib/python3.10/site-packages/airflow/models/taskinstance.py", line 433, in _execute_task
    result = execute_callable(context=context, **execute_callable_kwargs)
  File "/home/airflow/.local/lib/python3.10/site-packages/airflow/providers/docker/operators/docker.py", line 502, in execute
    return self._run_image()
  File "/home/airflow/.local/lib/python3.10/site-packages/airflow/providers/docker/operators/docker.py", line 376, in _run_image
    return self._run_image_with_mounts(self.mounts, add_tmp_variable=False)
  File "/home/airflow/.local/lib/python3.10/site-packages/airflow/providers/docker/operators/docker.py", line 437, in _run_image_with_mounts
    raise DockerContainerFailedException(f"Docker container failed: {result!r}", logs=log_lines)
airflow.providers.docker.exceptions.DockerContainerFailedException: Docker container failed: {'StatusCode': 1}
[2025-06-17T15:01:18.228+0000] {taskinstance.py:1138} INFO - Marking task as UP_FOR_RETRY. dag_id=northwind, task_id=extra√ß√£o_postgres, execution_date=20250617T150111, start_date=20250617T150113, end_date=20250617T150118
[2025-06-17T15:01:18.240+0000] {standard_task_runner.py:107} ERROR - Failed to execute job 8 for task extra√ß√£o_postgres (Docker container failed: {'StatusCode': 1}; 172)
[2025-06-17T15:01:18.264+0000] {local_task_job_runner.py:234} INFO - Task exited with return code 1
[2025-06-17T15:01:18.288+0000] {taskinstance.py:3280} INFO - 0 downstream tasks scheduled from follow-on schedule check
