[2025-06-17T21:01:04.822+0000] {taskinstance.py:1956} INFO - Dependencies all met for dep_context=non-requeueable deps ti=<TaskInstance: northwind.extração_postgres manual__2025-06-17T21:01:03.301418+00:00 [queued]>
[2025-06-17T21:01:04.836+0000] {taskinstance.py:1956} INFO - Dependencies all met for dep_context=requeueable deps ti=<TaskInstance: northwind.extração_postgres manual__2025-06-17T21:01:03.301418+00:00 [queued]>
[2025-06-17T21:01:04.836+0000] {taskinstance.py:2170} INFO - Starting attempt 1 of 2
[2025-06-17T21:01:04.865+0000] {taskinstance.py:2191} INFO - Executing <Task(DockerOperator): extração_postgres> on 2025-06-17 21:01:03.301418+00:00
[2025-06-17T21:01:04.889+0000] {standard_task_runner.py:60} INFO - Started process 239 to run task
[2025-06-17T21:01:04.959+0000] {standard_task_runner.py:87} INFO - Running: ['***', 'tasks', 'run', 'northwind', 'extração_postgres', 'manual__2025-06-17T21:01:03.301418+00:00', '--job-id', '7', '--raw', '--subdir', 'DAGS_FOLDER/dag.py', '--cfg-path', '/tmp/tmpi8ldyvc8']
[2025-06-17T21:01:04.963+0000] {standard_task_runner.py:88} INFO - Job 7: Subtask extração_postgres
[2025-06-17T21:01:05.474+0000] {task_command.py:423} INFO - Running <TaskInstance: northwind.extração_postgres manual__2025-06-17T21:01:03.301418+00:00 [running]> on host 68f227576ce2
[2025-06-17T21:01:05.720+0000] {taskinstance.py:2480} INFO - Exporting env vars: AIRFLOW_CTX_DAG_EMAIL='lrbf@cin.ufpe.br' AIRFLOW_CTX_DAG_OWNER='***' AIRFLOW_CTX_DAG_ID='northwind' AIRFLOW_CTX_TASK_ID='extração_postgres' AIRFLOW_CTX_EXECUTION_DATE='2025-06-17T21:01:03.301418+00:00' AIRFLOW_CTX_TRY_NUMBER='1' AIRFLOW_CTX_DAG_RUN_ID='manual__2025-06-17T21:01:03.301418+00:00'
[2025-06-17T21:01:05.772+0000] {docker.py:359} INFO - Starting docker container from image indicium_pipeline-meltano:latest
[2025-06-17T21:01:07.227+0000] {taskinstance.py:2698} ERROR - Task failed with exception
Traceback (most recent call last):
  File "/home/airflow/.local/lib/python3.10/site-packages/docker/api/client.py", line 265, in _raise_for_status
    response.raise_for_status()
  File "/home/airflow/.local/lib/python3.10/site-packages/requests/models.py", line 1021, in raise_for_status
    raise HTTPError(http_error_msg, response=self)
requests.exceptions.HTTPError: 400 Client Error: Bad Request for url: http+docker://localhost/v1.45/containers/b0f5f39e4348949594913da9a4d53ef4be33f6904e69f6bcbfa95438541dfa5c/start

The above exception was the direct cause of the following exception:

Traceback (most recent call last):
  File "/home/airflow/.local/lib/python3.10/site-packages/airflow/models/taskinstance.py", line 433, in _execute_task
    result = execute_callable(context=context, **execute_callable_kwargs)
  File "/home/airflow/.local/lib/python3.10/site-packages/airflow/providers/docker/operators/docker.py", line 502, in execute
    return self._run_image()
  File "/home/airflow/.local/lib/python3.10/site-packages/airflow/providers/docker/operators/docker.py", line 376, in _run_image
    return self._run_image_with_mounts(self.mounts, add_tmp_variable=False)
  File "/home/airflow/.local/lib/python3.10/site-packages/airflow/providers/docker/operators/docker.py", line 423, in _run_image_with_mounts
    self.cli.start(self.container["Id"])
  File "/home/airflow/.local/lib/python3.10/site-packages/docker/utils/decorators.py", line 19, in wrapped
    return f(self, resource_id, *args, **kwargs)
  File "/home/airflow/.local/lib/python3.10/site-packages/docker/api/container.py", line 1135, in start
    self._raise_for_status(res)
  File "/home/airflow/.local/lib/python3.10/site-packages/docker/api/client.py", line 267, in _raise_for_status
    raise create_api_error_from_http_exception(e) from e
  File "/home/airflow/.local/lib/python3.10/site-packages/docker/errors.py", line 39, in create_api_error_from_http_exception
    raise cls(e, response=response, explanation=explanation) from e
docker.errors.APIError: 400 Client Error for http+docker://localhost/v1.45/containers/b0f5f39e4348949594913da9a4d53ef4be33f6904e69f6bcbfa95438541dfa5c/start: Bad Request ("failed to create task for container: failed to create shim task: OCI runtime create failed: runc create failed: unable to start container process: exec: "./entrypoint.sh": stat ./entrypoint.sh: no such file or directory: unknown")
[2025-06-17T21:01:07.236+0000] {taskinstance.py:1138} INFO - Marking task as UP_FOR_RETRY. dag_id=northwind, task_id=extração_postgres, execution_date=20250617T210103, start_date=20250617T210104, end_date=20250617T210107
[2025-06-17T21:01:07.248+0000] {standard_task_runner.py:107} ERROR - Failed to execute job 7 for task extração_postgres (400 Client Error for http+docker://localhost/v1.45/containers/b0f5f39e4348949594913da9a4d53ef4be33f6904e69f6bcbfa95438541dfa5c/start: Bad Request ("failed to create task for container: failed to create shim task: OCI runtime create failed: runc create failed: unable to start container process: exec: "./entrypoint.sh": stat ./entrypoint.sh: no such file or directory: unknown"); 239)
[2025-06-17T21:01:07.294+0000] {local_task_job_runner.py:234} INFO - Task exited with return code 1
[2025-06-17T21:01:07.324+0000] {taskinstance.py:3280} INFO - 0 downstream tasks scheduled from follow-on schedule check
