[2025-06-25T20:18:08.571+0000] {taskinstance.py:1956} INFO - Dependencies all met for dep_context=non-requeueable deps ti=<TaskInstance: northwind.carregamento_postgres manual__2025-06-25T20:12:05.237784+00:00 [queued]>
[2025-06-25T20:18:08.591+0000] {taskinstance.py:1956} INFO - Dependencies all met for dep_context=requeueable deps ti=<TaskInstance: northwind.carregamento_postgres manual__2025-06-25T20:12:05.237784+00:00 [queued]>
[2025-06-25T20:18:08.591+0000] {taskinstance.py:2170} INFO - Starting attempt 2 of 2
[2025-06-25T20:18:08.618+0000] {taskinstance.py:2191} INFO - Executing <Task(DockerOperator): carregamento_postgres> on 2025-06-25 20:12:05.237784+00:00
[2025-06-25T20:18:08.636+0000] {standard_task_runner.py:60} INFO - Started process 243 to run task
[2025-06-25T20:18:08.645+0000] {standard_task_runner.py:87} INFO - Running: ['***', 'tasks', 'run', 'northwind', 'carregamento_postgres', 'manual__2025-06-25T20:12:05.237784+00:00', '--job-id', '134', '--raw', '--subdir', 'DAGS_FOLDER/dag.py', '--cfg-path', '/tmp/tmpibf2k6hm']
[2025-06-25T20:18:08.655+0000] {standard_task_runner.py:88} INFO - Job 134: Subtask carregamento_postgres
[2025-06-25T20:18:08.777+0000] {task_command.py:423} INFO - Running <TaskInstance: northwind.carregamento_postgres manual__2025-06-25T20:12:05.237784+00:00 [running]> on host 6afc1f3750fb
[2025-06-25T20:18:08.922+0000] {taskinstance.py:2480} INFO - Exporting env vars: AIRFLOW_CTX_DAG_EMAIL='lrbf@cin.ufpe.br' AIRFLOW_CTX_DAG_OWNER='***' AIRFLOW_CTX_DAG_ID='northwind' AIRFLOW_CTX_TASK_ID='carregamento_postgres' AIRFLOW_CTX_EXECUTION_DATE='2025-06-25T20:12:05.237784+00:00' AIRFLOW_CTX_TRY_NUMBER='2' AIRFLOW_CTX_DAG_RUN_ID='manual__2025-06-25T20:12:05.237784+00:00'
[2025-06-25T20:18:09.376+0000] {docker.py:359} INFO - Starting docker container from image meltano:latest
[2025-06-25T20:18:10.551+0000] {docker.py:429} INFO - Running meltano install...
[2025-06-25T20:18:12.356+0000] {docker.py:429} INFO - [2m2025-06-25T20:18:12.355507Z[0m [[32m[1minfo     [0m] [1mInstalling 7 plugins          [0m
[2025-06-25T20:18:12.368+0000] {docker.py:429} INFO - [2m2025-06-25T20:18:12.367290Z[0m [[32m[1minfo     [0m] [1mInstalling extractor 'tap-postgres'[0m
[2025-06-25T20:18:12.384+0000] {docker.py:429} INFO - [2m2025-06-25T20:18:12.384005Z[0m [[32m[1minfo     [0m] [1mInstalling extractor 'tap-csv'[0m
[2025-06-25T20:18:12.399+0000] {docker.py:429} INFO - [2m2025-06-25T20:18:12.398382Z[0m [[32m[1minfo     [0m] [1mInstalling extractor 'tap-csv-latest'[0m
[2025-06-25T20:18:12.414+0000] {docker.py:429} INFO - [2m2025-06-25T20:18:12.414112Z[0m [[32m[1minfo     [0m] [1mInstalling loader 'target-postgres'[0m
[2025-06-25T20:18:12.434+0000] {docker.py:429} INFO - [2m2025-06-25T20:18:12.434152Z[0m [[32m[1minfo     [0m] [1mInstalling loader 'target-csv'[0m
[2025-06-25T20:18:12.455+0000] {docker.py:429} INFO - [2m2025-06-25T20:18:12.455176Z[0m [[32m[1minfo     [0m] [1mInstalling loader 'target-csv-postgres'[0m
[2025-06-25T20:18:12.480+0000] {docker.py:429} INFO - [2m2025-06-25T20:18:12.479845Z[0m [[32m[1minfo     [0m] [1mInstalling loader 'target-csv-csv'[0m
[2025-06-25T20:18:15.582+0000] {docker.py:429} INFO - [2m2025-06-25T20:18:15.557264Z[0m [[32m[1minfo     [0m] [1mInstalled loader 'target-postgres'[0m
[2025-06-25T20:18:15.599+0000] {docker.py:429} INFO - [2m2025-06-25T20:18:15.570427Z[0m [[32m[1minfo     [0m] [1mInstalled extractor 'tap-postgres'[0m
[2025-06-25T20:18:20.039+0000] {docker.py:429} INFO - [2m2025-06-25T20:18:20.029487Z[0m [[32m[1minfo     [0m] [1mInstalled extractor 'tap-csv' [0m
[2025-06-25T20:18:20.306+0000] {docker.py:429} INFO - [2m2025-06-25T20:18:20.305687Z[0m [[32m[1minfo     [0m] [1mInstalled extractor 'tap-csv-latest'[0m
[2025-06-25T20:18:20.522+0000] {docker.py:429} INFO - [2m2025-06-25T20:18:20.522147Z[0m [[32m[1minfo     [0m] [1mInstalled loader 'target-csv' [0m
[2025-06-25T20:18:20.696+0000] {docker.py:429} INFO - [2m2025-06-25T20:18:20.695365Z[0m [[32m[1minfo     [0m] [1mInstalled loader 'target-csv-csv'[0m
[2025-06-25T20:18:20.747+0000] {docker.py:429} INFO - [2m2025-06-25T20:18:20.747259Z[0m [[32m[1minfo     [0m] [1mInstalled loader 'target-csv-postgres'[0m
[2025-06-25T20:18:20.749+0000] {docker.py:429} INFO - [2m2025-06-25T20:18:20.748510Z[0m [[32m[1minfo     [0m] [1mInstalled 7/7 plugins         [0m
[2025-06-25T20:18:22.340+0000] {docker.py:429} INFO - Meltano install completed. Executing command: meltano el tap-csv-latest target-postgres
[2025-06-25T20:18:23.541+0000] {docker.py:429} INFO - [2m2025-06-25T20:18:23.540338Z[0m [[32m[1minfo     [0m] [1mEnvironment 'dev' is active   [0m
[2025-06-25T20:18:23.974+0000] {docker.py:429} INFO - [2m2025-06-25T20:18:23.972434Z[0m [[32m[1minfo     [0m] [1mRunning extract & load...     [0m [36mname[0m=[35mmeltano[0m [36mrun_id[0m=[35ma864609c-3cbc-4aef-8193-11130399fb49[0m [36mstate_id[0m=[35m2025-06-25T201823--tap-csv-latest--target-postgres[0m
[2025-06-25T20:18:24.802+0000] {docker.py:429} INFO - [2m2025-06-25T20:18:24.801294Z[0m [[32m[1minfo     [0m] [1mConfig validation error: '/opt/meltano/config/tap-csv-latest.json' is not of type 'array', 'null' in config['files'][0m [36mcmd_type[0m=[35mextractor[0m [36mname[0m=[35mtap-csv-latest[0m [36mrun_id[0m=[35ma864609c-3cbc-4aef-8193-11130399fb49[0m [36mstate_id[0m=[35m2025-06-25T201823--tap-csv-latest--target-postgres[0m [36mstdio[0m=[35mstderr[0m
[2025-06-25T20:18:24.939+0000] {docker.py:429} INFO - [2m2025-06-25T20:18:24.938728Z[0m [[32m[1minfo     [0m] [1mtarget-postgres v0.4.3, Meltano SDK v0.47.2[0m [36mcmd_type[0m=[35mloader[0m [36mname[0m=[35mtarget-postgres[0m [36mrun_id[0m=[35ma864609c-3cbc-4aef-8193-11130399fb49[0m [36mstate_id[0m=[35m2025-06-25T201823--tap-csv-latest--target-postgres[0m [36mstdio[0m=[35mstderr[0m
[2025-06-25T20:18:24.940+0000] {docker.py:429} INFO - [2m2025-06-25T20:18:24.939170Z[0m [[32m[1minfo     [0m] [1mSkipping parse of env var settings...[0m [36mcmd_type[0m=[35mloader[0m [36mname[0m=[35mtarget-postgres[0m [36mrun_id[0m=[35ma864609c-3cbc-4aef-8193-11130399fb49[0m [36mstate_id[0m=[35m2025-06-25T201823--tap-csv-latest--target-postgres[0m [36mstdio[0m=[35mstderr[0m
[2025-06-25T20:18:24.940+0000] {docker.py:429} INFO - [2m2025-06-25T20:18:24.939522Z[0m [[32m[1minfo     [0m] [1mTraceback (most recent call last):[0m [36mcmd_type[0m=[35mloader[0m [36mname[0m=[35mtarget-postgres[0m [36mrun_id[0m=[35ma864609c-3cbc-4aef-8193-11130399fb49[0m [36mstate_id[0m=[35m2025-06-25T201823--tap-csv-latest--target-postgres[0m [36mstdio[0m=[35mstderr[0m
[2025-06-25T20:18:24.941+0000] {docker.py:429} INFO - [2m2025-06-25T20:18:24.939774Z[0m [[32m[1minfo     [0m] [1m  File "/opt/meltano/.meltano/loaders/target-postgres/venv/bin/target-postgres", line 8, in <module>[0m [36mcmd_type[0m=[35mloader[0m [36mname[0m=[35mtarget-postgres[0m [36mrun_id[0m=[35ma864609c-3cbc-4aef-8193-11130399fb49[0m [36mstate_id[0m=[35m2025-06-25T201823--tap-csv-latest--target-postgres[0m [36mstdio[0m=[35mstderr[0m
[2025-06-25T20:18:24.941+0000] {docker.py:429} INFO - [2m2025-06-25T20:18:24.939967Z[0m [[32m[1minfo     [0m] [1m    sys.exit(TargetPostgres.cli())[0m [36mcmd_type[0m=[35mloader[0m [36mname[0m=[35mtarget-postgres[0m [36mrun_id[0m=[35ma864609c-3cbc-4aef-8193-11130399fb49[0m [36mstate_id[0m=[35m2025-06-25T201823--tap-csv-latest--target-postgres[0m [36mstdio[0m=[35mstderr[0m
[2025-06-25T20:18:24.942+0000] {docker.py:429} INFO - [2m2025-06-25T20:18:24.940184Z[0m [[32m[1minfo     [0m] [1m  File "/opt/meltano/.meltano/loaders/target-postgres/venv/lib/python3.10/site-packages/click/core.py", line 1442, in __call__[0m [36mcmd_type[0m=[35mloader[0m [36mname[0m=[35mtarget-postgres[0m [36mrun_id[0m=[35ma864609c-3cbc-4aef-8193-11130399fb49[0m [36mstate_id[0m=[35m2025-06-25T201823--tap-csv-latest--target-postgres[0m [36mstdio[0m=[35mstderr[0m
[2025-06-25T20:18:24.942+0000] {docker.py:429} INFO - [2m2025-06-25T20:18:24.941283Z[0m [[32m[1minfo     [0m] [1m    return self.main(*args, **kwargs)[0m [36mcmd_type[0m=[35mloader[0m [36mname[0m=[35mtarget-postgres[0m [36mrun_id[0m=[35ma864609c-3cbc-4aef-8193-11130399fb49[0m [36mstate_id[0m=[35m2025-06-25T201823--tap-csv-latest--target-postgres[0m [36mstdio[0m=[35mstderr[0m
[2025-06-25T20:18:24.943+0000] {docker.py:429} INFO - [2m2025-06-25T20:18:24.941904Z[0m [[32m[1minfo     [0m] [1m  File "/opt/meltano/.meltano/loaders/target-postgres/venv/lib/python3.10/site-packages/click/core.py", line 1363, in main[0m [36mcmd_type[0m=[35mloader[0m [36mname[0m=[35mtarget-postgres[0m [36mrun_id[0m=[35ma864609c-3cbc-4aef-8193-11130399fb49[0m [36mstate_id[0m=[35m2025-06-25T201823--tap-csv-latest--target-postgres[0m [36mstdio[0m=[35mstderr[0m
[2025-06-25T20:18:24.943+0000] {docker.py:429} INFO - [2m2025-06-25T20:18:24.942862Z[0m [[32m[1minfo     [0m] [1m    rv = self.invoke(ctx)     [0m [36mcmd_type[0m=[35mloader[0m [36mname[0m=[35mtarget-postgres[0m [36mrun_id[0m=[35ma864609c-3cbc-4aef-8193-11130399fb49[0m [36mstate_id[0m=[35m2025-06-25T201823--tap-csv-latest--target-postgres[0m [36mstdio[0m=[35mstderr[0m
[2025-06-25T20:18:24.943+0000] {docker.py:429} INFO - [2m2025-06-25T20:18:24.943164Z[0m [[32m[1minfo     [0m] [1m  File "/opt/meltano/.meltano/loaders/target-postgres/venv/lib/python3.10/site-packages/singer_sdk/plugin_base.py", line 97, in invoke[0m [36mcmd_type[0m=[35mloader[0m [36mname[0m=[35mtarget-postgres[0m [36mrun_id[0m=[35ma864609c-3cbc-4aef-8193-11130399fb49[0m [36mstate_id[0m=[35m2025-06-25T201823--tap-csv-latest--target-postgres[0m [36mstdio[0m=[35mstderr[0m
[2025-06-25T20:18:24.945+0000] {docker.py:429} INFO - [2m2025-06-25T20:18:24.943433Z[0m [[32m[1minfo     [0m] [1m    return super().invoke(ctx)[0m [36mcmd_type[0m=[35mloader[0m [36mname[0m=[35mtarget-postgres[0m [36mrun_id[0m=[35ma864609c-3cbc-4aef-8193-11130399fb49[0m [36mstate_id[0m=[35m2025-06-25T201823--tap-csv-latest--target-postgres[0m [36mstdio[0m=[35mstderr[0m
[2m2025-06-25T20:18:24.943645Z[0m [[32m[1minfo     [0m] [1m  File "/opt/meltano/.meltano/loaders/target-postgres/venv/lib/python3.10/site-packages/click/core.py", line 1226, in invoke[0m [36mcmd_type[0m=[35mloader[0m [36mname[0m=[35mtarget-postgres[0m [36mrun_id[0m=[35ma864609c-3cbc-4aef-8193-11130399fb49[0m [36mstate_id[0m=[35m2025-06-25T201823--tap-csv-latest--target-postgres[0m [36mstdio[0m=[35mstderr[0m
[2m2025-06-25T20:18:24.943867Z[0m [[32m[1minfo     [0m] [1m    return ctx.invoke(self.callback, **ctx.params)[0m [36mcmd_type[0m=[35mloader[0m [36mname[0m=[35mtarget-postgres[0m [36mrun_id[0m=[35ma864609c-3cbc-4aef-8193-11130399fb49[0m [36mstate_id[0m=[35m2025-06-25T201823--tap-csv-latest--target-postgres[0m [36mstdio[0m=[35mstderr[0m
[2m2025-06-25T20:18:24.944138Z[0m [[32m[1minfo     [0m] [1m  File "/opt/meltano/.meltano/loaders/target-postgres/venv/lib/python3.10/site-packages/click/core.py", line 794, in invoke[0m [36mcmd_type[0m=[35mloader[0m [36mname[0m=[35mtarget-postgres[0m [36mrun_id[0m=[35ma864609c-3cbc-4aef-8193-11130399fb49[0m [36mstate_id[0m=[35m2025-06-25T201823--tap-csv-latest--target-postgres[0m [36mstdio[0m=[35mstderr[0m
[2025-06-25T20:18:24.946+0000] {docker.py:429} INFO - [2m2025-06-25T20:18:24.944494Z[0m [[32m[1minfo     [0m] [1m    return callback(*args, **kwargs)[0m [36mcmd_type[0m=[35mloader[0m [36mname[0m=[35mtarget-postgres[0m [36mrun_id[0m=[35ma864609c-3cbc-4aef-8193-11130399fb49[0m [36mstate_id[0m=[35m2025-06-25T201823--tap-csv-latest--target-postgres[0m [36mstdio[0m=[35mstderr[0m
[2m2025-06-25T20:18:24.944795Z[0m [[32m[1minfo     [0m] [1m  File "/opt/meltano/.meltano/loaders/target-postgres/venv/lib/python3.10/site-packages/singer_sdk/target_base.py", line 583, in invoke[0m [36mcmd_type[0m=[35mloader[0m [36mname[0m=[35mtarget-postgres[0m [36mrun_id[0m=[35ma864609c-3cbc-4aef-8193-11130399fb49[0m [36mstate_id[0m=[35m2025-06-25T201823--tap-csv-latest--target-postgres[0m [36mstdio[0m=[35mstderr[0m
[2025-06-25T20:18:24.947+0000] {docker.py:429} INFO - [2m2025-06-25T20:18:24.945106Z[0m [[32m[1minfo     [0m] [1m    target = cls(             [0m [36mcmd_type[0m=[35mloader[0m [36mname[0m=[35mtarget-postgres[0m [36mrun_id[0m=[35ma864609c-3cbc-4aef-8193-11130399fb49[0m [36mstate_id[0m=[35m2025-06-25T201823--tap-csv-latest--target-postgres[0m [36mstdio[0m=[35mstderr[0m
[2025-06-25T20:18:24.947+0000] {docker.py:429} INFO - [2m2025-06-25T20:18:24.945317Z[0m [[32m[1minfo     [0m] [1m  File "/opt/meltano/.meltano/loaders/target-postgres/venv/lib/python3.10/site-packages/target_postgres/target.py", line 67, in __init__[0m [36mcmd_type[0m=[35mloader[0m [36mname[0m=[35mtarget-postgres[0m [36mrun_id[0m=[35ma864609c-3cbc-4aef-8193-11130399fb49[0m [36mstate_id[0m=[35m2025-06-25T201823--tap-csv-latest--target-postgres[0m [36mstdio[0m=[35mstderr[0m
[2025-06-25T20:18:24.947+0000] {docker.py:429} INFO - [2m2025-06-25T20:18:24.945568Z[0m [[32m[1minfo     [0m] [1m    and self.config.get("dialect+driver") is not None[0m [36mcmd_type[0m=[35mloader[0m [36mname[0m=[35mtarget-postgres[0m [36mrun_id[0m=[35ma864609c-3cbc-4aef-8193-11130399fb49[0m [36mstate_id[0m=[35m2025-06-25T201823--tap-csv-latest--target-postgres[0m [36mstdio[0m=[35mstderr[0m
[2m2025-06-25T20:18:24.945822Z[0m [[32m[1minfo     [0m] [1mAssertionError: Need either the sqlalchemy_url to be set or host, port, user, password, and dialect+driver to be set[0m [36mcmd_type[0m=[35mloader[0m [36mname[0m=[35mtarget-postgres[0m [36mrun_id[0m=[35ma864609c-3cbc-4aef-8193-11130399fb49[0m [36mstate_id[0m=[35m2025-06-25T201823--tap-csv-latest--target-postgres[0m [36mstdio[0m=[35mstderr[0m
[2025-06-25T20:18:25.048+0000] {docker.py:429} INFO - [2m2025-06-25T20:18:25.047484Z[0m [[31m[1merror    [0m] [1mExtraction failed             [0m [36mcode[0m=[35m1[0m [36mmessage[0m=[35m"Config validation error: '/opt/meltano/config/tap-csv-latest.json' is not of type 'array', 'null' in config['files']"[0m [36mname[0m=[35mmeltano[0m [36mrun_id[0m=[35ma864609c-3cbc-4aef-8193-11130399fb49[0m [36mstate_id[0m=[35m2025-06-25T201823--tap-csv-latest--target-postgres[0m
[2m2025-06-25T20:18:25.047771Z[0m [[31m[1merror    [0m] [1mLoading failed                [0m [36mcode[0m=[35m1[0m [36mmessage[0m=[35m'AssertionError: Need either the sqlalchemy_url to be set or host, port, user, password, and dialect+driver to be set'[0m [36mname[0m=[35mmeltano[0m [36mrun_id[0m=[35ma864609c-3cbc-4aef-8193-11130399fb49[0m [36mstate_id[0m=[35m2025-06-25T201823--tap-csv-latest--target-postgres[0m
[2025-06-25T20:18:25.049+0000] {docker.py:429} INFO - [2m2025-06-25T20:18:25.048228Z[0m [[32m[1minfo     [0m] [1mELT could not be completed: Extractor and loader failed.[0m [36mcmd_type[0m=[35melt[0m [36mname[0m=[35mmeltano[0m [36mrun_id[0m=[35ma864609c-3cbc-4aef-8193-11130399fb49[0m [36mstate_id[0m=[35m2025-06-25T201823--tap-csv-latest--target-postgres[0m [36mstdio[0m=[35mstderr[0m
[2025-06-25T20:18:25.049+0000] {docker.py:429} INFO - [2m2025-06-25T20:18:25.048519Z[0m [[32m[1minfo     [0m] [1mFor more detailed log messages re-run the command using 'meltano --log-level=debug ...' CLI flag.[0m [36mcmd_type[0m=[35melt[0m [36mname[0m=[35mmeltano[0m [36mrun_id[0m=[35ma864609c-3cbc-4aef-8193-11130399fb49[0m [36mstate_id[0m=[35m2025-06-25T201823--tap-csv-latest--target-postgres[0m [36mstdio[0m=[35mstderr[0m
[2025-06-25T20:18:25.049+0000] {docker.py:429} INFO - [2m2025-06-25T20:18:25.048731Z[0m [[32m[1minfo     [0m] [1mNote that you can also check the generated log file at '/opt/meltano/.meltano/logs/elt/2025-06-25T201823--tap-csv-latest--target-postgres/a864609c-3cbc-4aef-8193-11130399fb49/elt.log'.[0m [36mcmd_type[0m=[35melt[0m [36mname[0m=[35mmeltano[0m [36mrun_id[0m=[35ma864609c-3cbc-4aef-8193-11130399fb49[0m [36mstate_id[0m=[35m2025-06-25T201823--tap-csv-latest--target-postgres[0m [36mstdio[0m=[35mstderr[0m
[2025-06-25T20:18:25.049+0000] {docker.py:429} INFO - [2m2025-06-25T20:18:25.048963Z[0m [[32m[1minfo     [0m] [1mFor more information on debugging and logging: https://docs.meltano.com/reference/command-line-interface#debugging[0m [36mcmd_type[0m=[35melt[0m [36mname[0m=[35mmeltano[0m [36mrun_id[0m=[35ma864609c-3cbc-4aef-8193-11130399fb49[0m [36mstate_id[0m=[35m2025-06-25T201823--tap-csv-latest--target-postgres[0m [36mstdio[0m=[35mstderr[0m
[2025-06-25T20:18:25.072+0000] {docker.py:429} INFO - Need help fixing this problem? Visit http://melta.no/ for troubleshooting steps, or to
join our friendly Slack community.

ELT could not be completed: Extractor and loader failed.
For more detailed log messages re-run the command using 'meltano --log-level=debug ...' CLI flag.
Note that you can also check the generated log file at '/opt/meltano/.meltano/logs/elt/2025-06-25T201823--tap-csv-latest--target-postgres/a864609c-3cbc-4aef-8193-11130399fb49/elt.log'.
For more information on debugging and logging: https://docs.meltano.com/reference/command-line-interface#debugging
[2025-06-25T20:18:26.502+0000] {taskinstance.py:2698} ERROR - Task failed with exception
Traceback (most recent call last):
  File "/home/airflow/.local/lib/python3.10/site-packages/airflow/models/taskinstance.py", line 433, in _execute_task
    result = execute_callable(context=context, **execute_callable_kwargs)
  File "/home/airflow/.local/lib/python3.10/site-packages/airflow/providers/docker/operators/docker.py", line 502, in execute
    return self._run_image()
  File "/home/airflow/.local/lib/python3.10/site-packages/airflow/providers/docker/operators/docker.py", line 376, in _run_image
    return self._run_image_with_mounts(self.mounts, add_tmp_variable=False)
  File "/home/airflow/.local/lib/python3.10/site-packages/airflow/providers/docker/operators/docker.py", line 437, in _run_image_with_mounts
    raise DockerContainerFailedException(f"Docker container failed: {result!r}", logs=log_lines)
airflow.providers.docker.exceptions.DockerContainerFailedException: Docker container failed: {'StatusCode': 1}
[2025-06-25T20:18:26.514+0000] {taskinstance.py:1138} INFO - Marking task as FAILED. dag_id=northwind, task_id=carregamento_postgres, execution_date=20250625T201205, start_date=20250625T201808, end_date=20250625T201826
[2025-06-25T20:18:26.678+0000] {logging_mixin.py:188} WARNING - /home/***/.local/lib/python3.10/site-packages/***/utils/email.py:154 RemovedInAirflow3Warning: Fetching SMTP credentials from configuration variables will be deprecated in a future release. Please set credentials using a connection instead.
[2025-06-25T20:18:26.681+0000] {configuration.py:1046} WARNING - section/key [smtp/smtp_user] not found in config
[2025-06-25T20:18:26.682+0000] {email.py:270} INFO - Email alerting: attempt 1
[2025-06-25T20:18:26.703+0000] {configuration.py:1046} WARNING - section/key [smtp/smtp_user] not found in config
[2025-06-25T20:18:26.703+0000] {email.py:270} INFO - Email alerting: attempt 1
[2025-06-25T20:18:26.704+0000] {taskinstance.py:826} ERROR - Failed to send email to: ['lrbf@cin.ufpe.br']
Traceback (most recent call last):
  File "/home/airflow/.local/lib/python3.10/site-packages/airflow/models/taskinstance.py", line 2334, in _run_raw_task
    self._execute_task_with_callbacks(context, test_mode, session=session)
  File "/home/airflow/.local/lib/python3.10/site-packages/airflow/models/taskinstance.py", line 2499, in _execute_task_with_callbacks
    result = self._execute_task(context, task_orig)
  File "/home/airflow/.local/lib/python3.10/site-packages/airflow/models/taskinstance.py", line 2516, in _execute_task
    return _execute_task(self, context, task_orig)
  File "/home/airflow/.local/lib/python3.10/site-packages/airflow/models/taskinstance.py", line 433, in _execute_task
    result = execute_callable(context=context, **execute_callable_kwargs)
  File "/home/airflow/.local/lib/python3.10/site-packages/airflow/providers/docker/operators/docker.py", line 502, in execute
    return self._run_image()
  File "/home/airflow/.local/lib/python3.10/site-packages/airflow/providers/docker/operators/docker.py", line 376, in _run_image
    return self._run_image_with_mounts(self.mounts, add_tmp_variable=False)
  File "/home/airflow/.local/lib/python3.10/site-packages/airflow/providers/docker/operators/docker.py", line 437, in _run_image_with_mounts
    raise DockerContainerFailedException(f"Docker container failed: {result!r}", logs=log_lines)
airflow.providers.docker.exceptions.DockerContainerFailedException: Docker container failed: {'StatusCode': 1}

During handling of the above exception, another exception occurred:

Traceback (most recent call last):
  File "/home/airflow/.local/lib/python3.10/site-packages/airflow/models/taskinstance.py", line 1000, in _email_alert
    send_email(task.email, subject, html_content)
  File "/home/airflow/.local/lib/python3.10/site-packages/airflow/utils/email.py", line 80, in send_email
    return backend(
  File "/home/airflow/.local/lib/python3.10/site-packages/airflow/utils/email.py", line 154, in send_email_smtp
    send_mime_email(e_from=mail_from, e_to=recipients, mime_msg=msg, conn_id=conn_id, dryrun=dryrun)
  File "/home/airflow/.local/lib/python3.10/site-packages/airflow/utils/email.py", line 272, in send_mime_email
    smtp_conn = _get_smtp_connection(smtp_host, smtp_port, smtp_timeout, smtp_ssl)
  File "/home/airflow/.local/lib/python3.10/site-packages/airflow/utils/email.py", line 316, in _get_smtp_connection
    return smtplib.SMTP(host=host, port=port, timeout=timeout)
  File "/usr/local/lib/python3.10/smtplib.py", line 255, in __init__
    (code, msg) = self.connect(host, port)
  File "/usr/local/lib/python3.10/smtplib.py", line 341, in connect
    self.sock = self._get_socket(host, port, self.timeout)
  File "/usr/local/lib/python3.10/smtplib.py", line 312, in _get_socket
    return socket.create_connection((host, port), timeout,
  File "/usr/local/lib/python3.10/socket.py", line 845, in create_connection
    raise err
  File "/usr/local/lib/python3.10/socket.py", line 833, in create_connection
    sock.connect(sa)
ConnectionRefusedError: [Errno 111] Connection refused

During handling of the above exception, another exception occurred:

Traceback (most recent call last):
  File "/home/airflow/.local/lib/python3.10/site-packages/airflow/models/taskinstance.py", line 824, in _handle_failure
    task_instance.email_alert(error, failure_context["task"])
  File "/home/airflow/.local/lib/python3.10/site-packages/airflow/models/taskinstance.py", line 2946, in email_alert
    _email_alert(task_instance=self, exception=exception, task=task)
  File "/home/airflow/.local/lib/python3.10/site-packages/airflow/models/taskinstance.py", line 1002, in _email_alert
    send_email(task.email, subject, html_content_err)
  File "/home/airflow/.local/lib/python3.10/site-packages/airflow/utils/email.py", line 80, in send_email
    return backend(
  File "/home/airflow/.local/lib/python3.10/site-packages/airflow/utils/email.py", line 154, in send_email_smtp
    send_mime_email(e_from=mail_from, e_to=recipients, mime_msg=msg, conn_id=conn_id, dryrun=dryrun)
  File "/home/airflow/.local/lib/python3.10/site-packages/airflow/utils/email.py", line 272, in send_mime_email
    smtp_conn = _get_smtp_connection(smtp_host, smtp_port, smtp_timeout, smtp_ssl)
  File "/home/airflow/.local/lib/python3.10/site-packages/airflow/utils/email.py", line 316, in _get_smtp_connection
    return smtplib.SMTP(host=host, port=port, timeout=timeout)
  File "/usr/local/lib/python3.10/smtplib.py", line 255, in __init__
    (code, msg) = self.connect(host, port)
  File "/usr/local/lib/python3.10/smtplib.py", line 341, in connect
    self.sock = self._get_socket(host, port, self.timeout)
  File "/usr/local/lib/python3.10/smtplib.py", line 312, in _get_socket
    return socket.create_connection((host, port), timeout,
  File "/usr/local/lib/python3.10/socket.py", line 845, in create_connection
    raise err
  File "/usr/local/lib/python3.10/socket.py", line 833, in create_connection
    sock.connect(sa)
ConnectionRefusedError: [Errno 111] Connection refused
[2025-06-25T20:18:26.745+0000] {standard_task_runner.py:107} ERROR - Failed to execute job 134 for task carregamento_postgres (Docker container failed: {'StatusCode': 1}; 243)
[2025-06-25T20:18:26.817+0000] {local_task_job_runner.py:234} INFO - Task exited with return code 1
[2025-06-25T20:18:26.875+0000] {taskinstance.py:3280} INFO - 0 downstream tasks scheduled from follow-on schedule check
