[2025-06-30T21:47:46.825+0000] {taskinstance.py:1956} INFO - Dependencies all met for dep_context=non-requeueable deps ti=<TaskInstance: northwind.carregamento_postgres manual__2025-06-30T21:40:11.196630+00:00 [queued]>
[2025-06-30T21:47:46.838+0000] {taskinstance.py:1956} INFO - Dependencies all met for dep_context=requeueable deps ti=<TaskInstance: northwind.carregamento_postgres manual__2025-06-30T21:40:11.196630+00:00 [queued]>
[2025-06-30T21:47:46.839+0000] {taskinstance.py:2170} INFO - Starting attempt 2 of 2
[2025-06-30T21:47:46.858+0000] {taskinstance.py:2191} INFO - Executing <Task(DockerOperator): carregamento_postgres> on 2025-06-30 21:40:11.196630+00:00
[2025-06-30T21:47:46.864+0000] {standard_task_runner.py:60} INFO - Started process 170 to run task
[2025-06-30T21:47:46.870+0000] {standard_task_runner.py:87} INFO - Running: ['***', 'tasks', 'run', 'northwind', 'carregamento_postgres', 'manual__2025-06-30T21:40:11.196630+00:00', '--job-id', '15', '--raw', '--subdir', 'DAGS_FOLDER/dag.py', '--cfg-path', '/tmp/tmp11g7qjd2']
[2025-06-30T21:47:46.874+0000] {standard_task_runner.py:88} INFO - Job 15: Subtask carregamento_postgres
[2025-06-30T21:47:47.016+0000] {task_command.py:423} INFO - Running <TaskInstance: northwind.carregamento_postgres manual__2025-06-30T21:40:11.196630+00:00 [running]> on host b647631a2a81
[2025-06-30T21:47:47.259+0000] {taskinstance.py:2480} INFO - Exporting env vars: AIRFLOW_CTX_DAG_EMAIL='lrbf@cin.ufpe.br' AIRFLOW_CTX_DAG_OWNER='***' AIRFLOW_CTX_DAG_ID='northwind' AIRFLOW_CTX_TASK_ID='carregamento_postgres' AIRFLOW_CTX_EXECUTION_DATE='2025-06-30T21:40:11.196630+00:00' AIRFLOW_CTX_TRY_NUM***ER='2' AIRFLOW_CTX_DAG_RUN_ID='manual__2025-06-30T21:40:11.196630+00:00'
[2025-06-30T21:47:47.364+0000] {docker.py:359} INFO - Starting docker container from image meltano:latest
[2025-06-30T21:47:47.955+0000] {docker.py:429} INFO - Running meltano install...
[2025-06-30T21:47:50.326+0000] {docker.py:429} INFO - [2m2025-06-30T21:47:50.325397Z[0m [[32m[1minfo     [0m] [1mInstalling 7 plugins          [0m
[2025-06-30T21:47:50.347+0000] {docker.py:429} INFO - [2m2025-06-30T21:47:50.347249Z[0m [[32m[1minfo     [0m] [1mInstalling extractor 'tap-postgres'[0m
[2025-06-30T21:47:50.380+0000] {docker.py:429} INFO - [2m2025-06-30T21:47:50.379703Z[0m [[32m[1minfo     [0m] [1mInstalling extractor 'tap-csv'[0m
[2025-06-30T21:47:50.413+0000] {docker.py:429} INFO - [2m2025-06-30T21:47:50.412785Z[0m [[32m[1minfo     [0m] [1mInstalling extractor 'tap-csv-latest'[0m
[2025-06-30T21:47:50.443+0000] {docker.py:429} INFO - [2m2025-06-30T21:47:50.442471Z[0m [[32m[1minfo     [0m] [1mInstalling loader 'target-postgres'[0m
[2025-06-30T21:47:50.478+0000] {docker.py:429} INFO - [2m2025-06-30T21:47:50.477788Z[0m [[32m[1minfo     [0m] [1mInstalling loader 'target-csv'[0m
[2025-06-30T21:47:50.515+0000] {docker.py:429} INFO - [2m2025-06-30T21:47:50.514638Z[0m [[32m[1minfo     [0m] [1mInstalling loader 'target-csv-postgres'[0m
[2025-06-30T21:47:50.554+0000] {docker.py:429} INFO - [2m2025-06-30T21:47:50.551895Z[0m [[32m[1minfo     [0m] [1mInstalling loader 'target-csv-csv'[0m
[2025-06-30T21:47:52.460+0000] {docker.py:429} INFO - [2m2025-06-30T21:47:52.458663Z[0m [[32m[1minfo     [0m] [1mInstalled extractor 'tap-postgres'[0m
[2025-06-30T21:47:52.489+0000] {docker.py:429} INFO - [2m2025-06-30T21:47:52.488383Z[0m [[32m[1minfo     [0m] [1mInstalled loader 'target-postgres'[0m
[2025-06-30T21:47:59.044+0000] {docker.py:429} INFO - [2m2025-06-30T21:47:59.043051Z[0m [[32m[1minfo     [0m] [1mInstalled extractor 'tap-csv-latest'[0m
[2025-06-30T21:47:59.046+0000] {docker.py:429} INFO - [2m2025-06-30T21:47:59.045633Z[0m [[32m[1minfo     [0m] [1mInstalled extractor 'tap-csv' [0m
[2025-06-30T21:48:00.411+0000] {docker.py:429} INFO - [2m2025-06-30T21:48:00.410701Z[0m [[32m[1minfo     [0m] [1mInstalled loader 'target-csv' [0m
[2025-06-30T21:48:00.472+0000] {docker.py:429} INFO - [2m2025-06-30T21:48:00.471211Z[0m [[32m[1minfo     [0m] [1mInstalled loader 'target-csv-csv'[0m
[2025-06-30T21:48:00.488+0000] {docker.py:429} INFO - [2m2025-06-30T21:48:00.487243Z[0m [[32m[1minfo     [0m] [1mInstalled loader 'target-csv-postgres'[0m
[2025-06-30T21:48:00.488+0000] {docker.py:429} INFO - [2m2025-06-30T21:48:00.487748Z[0m [[32m[1minfo     [0m] [1mInstalled 7/7 plugins         [0m
[2025-06-30T21:48:01.711+0000] {docker.py:429} INFO - Meltano install completed. Executing command: meltano el tap-csv-latest target-postgres
[2025-06-30T21:48:03.228+0000] {docker.py:429} INFO - [2m2025-06-30T21:48:03.227906Z[0m [[32m[1minfo     [0m] [1mEnvironment 'dev' is active   [0m
[2025-06-30T21:48:03.796+0000] {docker.py:429} INFO - [2m2025-06-30T21:48:03.795555Z[0m [[32m[1minfo     [0m] [1mRunning extract & load...     [0m [36mname[0m=[35mmeltano[0m [36mrun_id[0m=[35m87055bf1-021d-44ae-8b97-f7ccd51bcfb1[0m [36mstate_id[0m=[35m2025-06-30T214803--tap-csv-latest--target-postgres[0m
[2025-06-30T21:48:04.927+0000] {docker.py:429} INFO - [2m2025-06-30T21:48:04.926201Z[0m [[32m[1minfo     [0m] [1mNo CSV file definitions found.[0m [36mcmd_type[0m=[35mextractor[0m [36mname[0m=[35mtap-csv-latest[0m [36mrun_id[0m=[35m87055bf1-021d-44ae-8b97-f7ccd51bcfb1[0m [36mstate_id[0m=[35m2025-06-30T214803--tap-csv-latest--target-postgres[0m [36mstdio[0m=[35mstderr[0m
[2025-06-30T21:48:05.162+0000] {docker.py:429} INFO - [2m2025-06-30T21:48:05.162159Z[0m [[32m[1minfo     [0m] [1mtarget-postgres v0.4.3, Meltano SDK v0.47.4[0m [36mcmd_type[0m=[35mloader[0m [36mname[0m=[35mtarget-postgres[0m [36mrun_id[0m=[35m87055bf1-021d-44ae-8b97-f7ccd51bcfb1[0m [36mstate_id[0m=[35m2025-06-30T214803--tap-csv-latest--target-postgres[0m [36mstdio[0m=[35mstderr[0m
[2025-06-30T21:48:05.164+0000] {docker.py:429} INFO - [2m2025-06-30T21:48:05.163942Z[0m [[32m[1minfo     [0m] [1m/opt/meltano/.meltano/loaders/target-postgres/venv/lib/python3.9/site-packages/singer_sdk/plugin_base.py:715: SingerSDKDeprecationWarning: Passing a list of config file paths is deprecated. Please pass the config as a dictionary instead.[0m [36mcmd_type[0m=[35mloader[0m [36mname[0m=[35mtarget-postgres[0m [36mrun_id[0m=[35m87055bf1-021d-44ae-8b97-f7ccd51bcfb1[0m [36mstate_id[0m=[35m2025-06-30T214803--tap-csv-latest--target-postgres[0m [36mstdio[0m=[35mstderr[0m
[2025-06-30T21:48:05.165+0000] {docker.py:429} INFO - [2m2025-06-30T21:48:05.164380Z[0m [[32m[1minfo     [0m] [1m  super().__init__(           [0m [36mcmd_type[0m=[35mloader[0m [36mname[0m=[35mtarget-postgres[0m [36mrun_id[0m=[35m87055bf1-021d-44ae-8b97-f7ccd51bcfb1[0m [36mstate_id[0m=[35m2025-06-30T214803--tap-csv-latest--target-postgres[0m [36mstdio[0m=[35mstderr[0m
[2025-06-30T21:48:05.165+0000] {docker.py:429} INFO - [2m2025-06-30T21:48:05.164707Z[0m [[32m[1minfo     [0m] [1m                              [0m [36mcmd_type[0m=[35mloader[0m [36mname[0m=[35mtarget-postgres[0m [36mrun_id[0m=[35m87055bf1-021d-44ae-8b97-f7ccd51bcfb1[0m [36mstate_id[0m=[35m2025-06-30T214803--tap-csv-latest--target-postgres[0m [36mstdio[0m=[35mstderr[0m
[2025-06-30T21:48:05.165+0000] {docker.py:429} INFO - [2m2025-06-30T21:48:05.165019Z[0m [[32m[1minfo     [0m] [1mSkipping parse of env var settings...[0m [36mcmd_type[0m=[35mloader[0m [36mname[0m=[35mtarget-postgres[0m [36mrun_id[0m=[35m87055bf1-021d-44ae-8b97-f7ccd51bcfb1[0m [36mstate_id[0m=[35m2025-06-30T214803--tap-csv-latest--target-postgres[0m [36mstdio[0m=[35mstderr[0m
[2025-06-30T21:48:05.166+0000] {docker.py:429} INFO - [2m2025-06-30T21:48:05.165429Z[0m [[32m[1minfo     [0m] [1mThe `dialect+driver` configuration option is deprecated. Please set it to `postgresql+psycopg`, as this will be the hard-coded value in the future.[0m [36mcmd_type[0m=[35mloader[0m [36mname[0m=[35mtarget-postgres[0m [36mrun_id[0m=[35m87055bf1-021d-44ae-8b97-f7ccd51bcfb1[0m [36mstate_id[0m=[35m2025-06-30T214803--tap-csv-latest--target-postgres[0m [36mstdio[0m=[35mstderr[0m
[2025-06-30T21:48:05.166+0000] {docker.py:429} INFO - [2m2025-06-30T21:48:05.165761Z[0m [[32m[1minfo     [0m] [1mReader 'target-postgres' completed processing 0 lines of input (0 schemas, 0 records, 0 batch manifests, 0 state messages, 0 activate version messages).[0m [36mcmd_type[0m=[35mloader[0m [36mname[0m=[35mtarget-postgres[0m [36mrun_id[0m=[35m87055bf1-021d-44ae-8b97-f7ccd51bcfb1[0m [36mstate_id[0m=[35m2025-06-30T214803--tap-csv-latest--target-postgres[0m [36mstdio[0m=[35mstderr[0m
[2025-06-30T21:48:05.289+0000] {docker.py:429} INFO - [2m2025-06-30T21:48:05.288333Z[0m [[31m[1merror    [0m] [1mExtraction failed             [0m [36mcode[0m=[35m1[0m [36mmessage[0m=[35m'No CSV file definitions found.'[0m [36mname[0m=[35mmeltano[0m [36mrun_id[0m=[35m87055bf1-021d-44ae-8b97-f7ccd51bcfb1[0m [36mstate_id[0m=[35m2025-06-30T214803--tap-csv-latest--target-postgres[0m
[2025-06-30T21:48:05.290+0000] {docker.py:429} INFO - [2m2025-06-30T21:48:05.289623Z[0m [[32m[1minfo     [0m] [1mELT could not be completed: Extractor failed.[0m [36mcmd_type[0m=[35melt[0m [36mname[0m=[35mmeltano[0m [36mrun_id[0m=[35m87055bf1-021d-44ae-8b97-f7ccd51bcfb1[0m [36mstate_id[0m=[35m2025-06-30T214803--tap-csv-latest--target-postgres[0m [36mstdio[0m=[35mstderr[0m
[2025-06-30T21:48:05.290+0000] {docker.py:429} INFO - [2m2025-06-30T21:48:05.290009Z[0m [[32m[1minfo     [0m] [1mFor more detailed log messages re-run the command using 'meltano --log-level=debug ...' CLI flag.[0m [36mcmd_type[0m=[35melt[0m [36mname[0m=[35mmeltano[0m [36mrun_id[0m=[35m87055bf1-021d-44ae-8b97-f7ccd51bcfb1[0m [36mstate_id[0m=[35m2025-06-30T214803--tap-csv-latest--target-postgres[0m [36mstdio[0m=[35mstderr[0m
[2025-06-30T21:48:05.291+0000] {docker.py:429} INFO - [2m2025-06-30T21:48:05.290270Z[0m [[32m[1minfo     [0m] [1mNote that you can also check the generated log file at '/opt/meltano/.meltano/logs/elt/2025-06-30T214803--tap-csv-latest--target-postgres/87055bf1-021d-44ae-8b97-f7ccd51bcfb1/elt.log'.[0m [36mcmd_type[0m=[35melt[0m [36mname[0m=[35mmeltano[0m [36mrun_id[0m=[35m87055bf1-021d-44ae-8b97-f7ccd51bcfb1[0m [36mstate_id[0m=[35m2025-06-30T214803--tap-csv-latest--target-postgres[0m [36mstdio[0m=[35mstderr[0m
[2025-06-30T21:48:05.291+0000] {docker.py:429} INFO - [2m2025-06-30T21:48:05.290592Z[0m [[32m[1minfo     [0m] [1mFor more information on debugging and logging: https://docs.meltano.com/reference/command-line-interface#debugging[0m [36mcmd_type[0m=[35melt[0m [36mname[0m=[35mmeltano[0m [36mrun_id[0m=[35m87055bf1-021d-44ae-8b97-f7ccd51bcfb1[0m [36mstate_id[0m=[35m2025-06-30T214803--tap-csv-latest--target-postgres[0m [36mstdio[0m=[35mstderr[0m
[2025-06-30T21:48:05.312+0000] {docker.py:429} INFO - Need help fixing this problem? Visit http://melta.no/ for troubleshooting steps, or to
join our friendly Slack community.

ELT could not be completed: Extractor failed.
For more detailed log messages re-run the command using 'meltano --log-level=debug ...' CLI flag.
Note that you can also check the generated log file at '/opt/meltano/.meltano/logs/elt/2025-06-30T214803--tap-csv-latest--target-postgres/87055bf1-021d-44ae-8b97-f7ccd51bcfb1/elt.log'.
For more information on debugging and logging: https://docs.meltano.com/reference/command-line-interface#debugging
[2025-06-30T21:48:06.830+0000] {taskinstance.py:2698} ERROR - Task failed with exception
Traceback (most recent call last):
  File "/home/airflow/.local/lib/python3.10/site-packages/airflow/models/taskinstance.py", line 433, in _execute_task
    result = execute_callable(context=context, **execute_callable_kwargs)
  File "/home/airflow/.local/lib/python3.10/site-packages/airflow/providers/docker/operators/docker.py", line 502, in execute
    return self._run_image()
  File "/home/airflow/.local/lib/python3.10/site-packages/airflow/providers/docker/operators/docker.py", line 376, in _run_image
    return self._run_image_with_mounts(self.mounts, add_tmp_variable=False)
  File "/home/airflow/.local/lib/python3.10/site-packages/airflow/providers/docker/operators/docker.py", line 437, in _run_image_with_mounts
    raise DockerContainerFailedException(f"Docker container failed: {result!r}", logs=log_lines)
airflow.providers.docker.exceptions.DockerContainerFailedException: Docker container failed: {'StatusCode': 1}
[2025-06-30T21:48:06.837+0000] {taskinstance.py:1138} INFO - Marking task as FAILED. dag_id=northwind, task_id=carregamento_postgres, execution_date=20250630T214011, start_date=20250630T214746, end_date=20250630T214806
[2025-06-30T21:48:06.873+0000] {logging_mixin.py:188} WARNING - /home/***/.local/lib/python3.10/site-packages/***/utils/email.py:154 RemovedInAirflow3Warning: Fetching SMTP credentials from configuration variables will be deprecated in a future release. Please set credentials using a connection instead.
[2025-06-30T21:48:06.874+0000] {configuration.py:1046} WARNING - section/key [smtp/smtp_user] not found in config
[2025-06-30T21:48:06.874+0000] {email.py:270} INFO - Email alerting: attempt 1
[2025-06-30T21:48:06.887+0000] {configuration.py:1046} WARNING - section/key [smtp/smtp_user] not found in config
[2025-06-30T21:48:06.888+0000] {email.py:270} INFO - Email alerting: attempt 1
[2025-06-30T21:48:06.889+0000] {taskinstance.py:826} ERROR - Failed to send email to: ['lrbf@cin.ufpe.br']
Traceback (most recent call last):
  File "/home/airflow/.local/lib/python3.10/site-packages/airflow/models/taskinstance.py", line 2334, in _run_raw_task
    self._execute_task_with_callbacks(context, test_mode, session=session)
  File "/home/airflow/.local/lib/python3.10/site-packages/airflow/models/taskinstance.py", line 2499, in _execute_task_with_callbacks
    result = self._execute_task(context, task_orig)
  File "/home/airflow/.local/lib/python3.10/site-packages/airflow/models/taskinstance.py", line 2516, in _execute_task
    return _execute_task(self, context, task_orig)
  File "/home/airflow/.local/lib/python3.10/site-packages/airflow/models/taskinstance.py", line 433, in _execute_task
    result = execute_callable(context=context, **execute_callable_kwargs)
  File "/home/airflow/.local/lib/python3.10/site-packages/airflow/providers/docker/operators/docker.py", line 502, in execute
    return self._run_image()
  File "/home/airflow/.local/lib/python3.10/site-packages/airflow/providers/docker/operators/docker.py", line 376, in _run_image
    return self._run_image_with_mounts(self.mounts, add_tmp_variable=False)
  File "/home/airflow/.local/lib/python3.10/site-packages/airflow/providers/docker/operators/docker.py", line 437, in _run_image_with_mounts
    raise DockerContainerFailedException(f"Docker container failed: {result!r}", logs=log_lines)
airflow.providers.docker.exceptions.DockerContainerFailedException: Docker container failed: {'StatusCode': 1}

During handling of the above exception, another exception occurred:

Traceback (most recent call last):
  File "/home/airflow/.local/lib/python3.10/site-packages/airflow/models/taskinstance.py", line 1000, in _email_alert
    send_email(task.email, subject, html_content)
  File "/home/airflow/.local/lib/python3.10/site-packages/airflow/utils/email.py", line 80, in send_email
    return backend(
  File "/home/airflow/.local/lib/python3.10/site-packages/airflow/utils/email.py", line 154, in send_email_smtp
    send_mime_email(e_from=mail_from, e_to=recipients, mime_msg=msg, conn_id=conn_id, dryrun=dryrun)
  File "/home/airflow/.local/lib/python3.10/site-packages/airflow/utils/email.py", line 272, in send_mime_email
    smtp_conn = _get_smtp_connection(smtp_host, smtp_port, smtp_timeout, smtp_ssl)
  File "/home/airflow/.local/lib/python3.10/site-packages/airflow/utils/email.py", line 316, in _get_smtp_connection
    return smtplib.SMTP(host=host, port=port, timeout=timeout)
  File "/usr/local/lib/python3.10/smtplib.py", line 255, in __init__
    (code, msg) = self.connect(host, port)
  File "/usr/local/lib/python3.10/smtplib.py", line 341, in connect
    self.sock = self._get_socket(host, port, self.timeout)
  File "/usr/local/lib/python3.10/smtplib.py", line 312, in _get_socket
    return socket.create_connection((host, port), timeout,
  File "/usr/local/lib/python3.10/socket.py", line 845, in create_connection
    raise err
  File "/usr/local/lib/python3.10/socket.py", line 833, in create_connection
    sock.connect(sa)
ConnectionRefusedError: [Errno 111] Connection refused

During handling of the above exception, another exception occurred:

Traceback (most recent call last):
  File "/home/airflow/.local/lib/python3.10/site-packages/airflow/models/taskinstance.py", line 824, in _handle_failure
    task_instance.email_alert(error, failure_context["task"])
  File "/home/airflow/.local/lib/python3.10/site-packages/airflow/models/taskinstance.py", line 2946, in email_alert
    _email_alert(task_instance=self, exception=exception, task=task)
  File "/home/airflow/.local/lib/python3.10/site-packages/airflow/models/taskinstance.py", line 1002, in _email_alert
    send_email(task.email, subject, html_content_err)
  File "/home/airflow/.local/lib/python3.10/site-packages/airflow/utils/email.py", line 80, in send_email
    return backend(
  File "/home/airflow/.local/lib/python3.10/site-packages/airflow/utils/email.py", line 154, in send_email_smtp
    send_mime_email(e_from=mail_from, e_to=recipients, mime_msg=msg, conn_id=conn_id, dryrun=dryrun)
  File "/home/airflow/.local/lib/python3.10/site-packages/airflow/utils/email.py", line 272, in send_mime_email
    smtp_conn = _get_smtp_connection(smtp_host, smtp_port, smtp_timeout, smtp_ssl)
  File "/home/airflow/.local/lib/python3.10/site-packages/airflow/utils/email.py", line 316, in _get_smtp_connection
    return smtplib.SMTP(host=host, port=port, timeout=timeout)
  File "/usr/local/lib/python3.10/smtplib.py", line 255, in __init__
    (code, msg) = self.connect(host, port)
  File "/usr/local/lib/python3.10/smtplib.py", line 341, in connect
    self.sock = self._get_socket(host, port, self.timeout)
  File "/usr/local/lib/python3.10/smtplib.py", line 312, in _get_socket
    return socket.create_connection((host, port), timeout,
  File "/usr/local/lib/python3.10/socket.py", line 845, in create_connection
    raise err
  File "/usr/local/lib/python3.10/socket.py", line 833, in create_connection
    sock.connect(sa)
ConnectionRefusedError: [Errno 111] Connection refused
[2025-06-30T21:48:06.908+0000] {standard_task_runner.py:107} ERROR - Failed to execute job 15 for task carregamento_postgres (Docker container failed: {'StatusCode': 1}; 170)
[2025-06-30T21:48:06.923+0000] {local_task_job_runner.py:234} INFO - Task exited with return code 1
[2025-06-30T21:48:06.943+0000] {taskinstance.py:3280} INFO - 0 downstream tasks scheduled from follow-on schedule check
