[2025-06-25T22:29:34.915+0000] {taskinstance.py:1956} INFO - Dependencies all met for dep_context=non-requeueable deps ti=<TaskInstance: northwind.gerar_config_csv_dinamica manual__2025-06-25T22:28:03.322197+00:00 [queued]>
[2025-06-25T22:29:34.928+0000] {taskinstance.py:1956} INFO - Dependencies all met for dep_context=requeueable deps ti=<TaskInstance: northwind.gerar_config_csv_dinamica manual__2025-06-25T22:28:03.322197+00:00 [queued]>
[2025-06-25T22:29:34.928+0000] {taskinstance.py:2170} INFO - Starting attempt 1 of 2
[2025-06-25T22:29:34.947+0000] {taskinstance.py:2191} INFO - Executing <Task(DockerOperator): gerar_config_csv_dinamica> on 2025-06-25 22:28:03.322197+00:00
[2025-06-25T22:29:34.953+0000] {standard_task_runner.py:60} INFO - Started process 190 to run task
[2025-06-25T22:29:34.957+0000] {standard_task_runner.py:87} INFO - Running: ['***', 'tasks', 'run', 'northwind', 'gerar_config_csv_dinamica', 'manual__2025-06-25T22:28:03.322197+00:00', '--job-id', '228', '--raw', '--subdir', 'DAGS_FOLDER/dag.py', '--cfg-path', '/tmp/tmp5bo1oxb9']
[2025-06-25T22:29:34.960+0000] {standard_task_runner.py:88} INFO - Job 228: Subtask gerar_config_csv_dinamica
[2025-06-25T22:29:35.015+0000] {task_command.py:423} INFO - Running <TaskInstance: northwind.gerar_config_csv_dinamica manual__2025-06-25T22:28:03.322197+00:00 [running]> on host 6afc1f3750fb
[2025-06-25T22:29:35.111+0000] {taskinstance.py:2480} INFO - Exporting env vars: AIRFLOW_CTX_DAG_EMAIL='lrbf@cin.ufpe.br' AIRFLOW_CTX_DAG_OWNER='***' AIRFLOW_CTX_DAG_ID='northwind' AIRFLOW_CTX_TASK_ID='gerar_config_csv_dinamica' AIRFLOW_CTX_EXECUTION_DATE='2025-06-25T22:28:03.322197+00:00' AIRFLOW_CTX_TRY_NUMBER='1' AIRFLOW_CTX_DAG_RUN_ID='manual__2025-06-25T22:28:03.322197+00:00'
[2025-06-25T22:29:35.384+0000] {docker.py:359} INFO - Starting docker container from image meltano:latest
[2025-06-25T22:29:35.392+0000] {docker.py:367} WARNING - Using remote engine or docker-in-docker and mounting temporary volume from host is not supported. Falling back to `mount_tmp_dir=False` mode. You can set `mount_tmp_dir` parameter to False to disable mounting and remove the warning
[2025-06-25T22:29:35.902+0000] {docker.py:429} INFO - Running meltano install...
[2025-06-25T22:29:38.038+0000] {docker.py:429} INFO - [2m2025-06-25T22:29:38.037247Z[0m [[32m[1minfo     [0m] [1mInstalling 7 plugins          [0m
[2025-06-25T22:29:38.063+0000] {docker.py:429} INFO - [2m2025-06-25T22:29:38.061775Z[0m [[32m[1minfo     [0m] [1mInstalling extractor 'tap-postgres'[0m
[2025-06-25T22:29:38.091+0000] {docker.py:429} INFO - [2m2025-06-25T22:29:38.090228Z[0m [[32m[1minfo     [0m] [1mInstalling extractor 'tap-csv'[0m
[2025-06-25T22:29:38.106+0000] {docker.py:429} INFO - [2m2025-06-25T22:29:38.105172Z[0m [[32m[1minfo     [0m] [1mInstalling extractor 'tap-csv-latest'[0m
[2025-06-25T22:29:38.131+0000] {docker.py:429} INFO - [2m2025-06-25T22:29:38.130513Z[0m [[32m[1minfo     [0m] [1mInstalling loader 'target-postgres'[0m
[2025-06-25T22:29:38.166+0000] {docker.py:429} INFO - [2m2025-06-25T22:29:38.165961Z[0m [[32m[1minfo     [0m] [1mInstalling loader 'target-csv'[0m
[2025-06-25T22:29:38.196+0000] {docker.py:429} INFO - [2m2025-06-25T22:29:38.195952Z[0m [[32m[1minfo     [0m] [1mInstalling loader 'target-csv-postgres'[0m
[2025-06-25T22:29:38.226+0000] {docker.py:429} INFO - [2m2025-06-25T22:29:38.225670Z[0m [[32m[1minfo     [0m] [1mInstalling loader 'target-csv-csv'[0m
[2025-06-25T22:29:40.041+0000] {docker.py:429} INFO - [2m2025-06-25T22:29:40.040491Z[0m [[32m[1minfo     [0m] [1mInstalled extractor 'tap-postgres'[0m
[2025-06-25T22:29:40.053+0000] {docker.py:429} INFO - [2m2025-06-25T22:29:40.052063Z[0m [[32m[1minfo     [0m] [1mInstalled loader 'target-postgres'[0m
[2025-06-25T22:29:48.283+0000] {docker.py:429} INFO - [2m2025-06-25T22:29:48.281938Z[0m [[32m[1minfo     [0m] [1mInstalled extractor 'tap-csv-latest'[0m
[2025-06-25T22:29:48.288+0000] {docker.py:429} INFO - [2m2025-06-25T22:29:48.286521Z[0m [[32m[1minfo     [0m] [1mInstalled extractor 'tap-csv' [0m
[2025-06-25T22:29:50.282+0000] {docker.py:429} INFO - [2m2025-06-25T22:29:50.281090Z[0m [[32m[1minfo     [0m] [1mInstalled loader 'target-csv' [0m
[2025-06-25T22:29:52.668+0000] {docker.py:429} INFO - [2m2025-06-25T22:29:52.667041Z[0m [[32m[1minfo     [0m] [1mInstalled loader 'target-csv-csv'[0m
[2025-06-25T22:29:52.711+0000] {docker.py:429} INFO - [2m2025-06-25T22:29:52.710771Z[0m [[32m[1minfo     [0m] [1mInstalled loader 'target-csv-postgres'[0m
[2025-06-25T22:29:52.712+0000] {docker.py:429} INFO - [2m2025-06-25T22:29:52.711300Z[0m [[32m[1minfo     [0m] [1mInstalled 7/7 plugins         [0m
[2025-06-25T22:29:54.268+0000] {docker.py:429} INFO - Meltano install completed. Executing command: python /opt/meltano/scripts/generate_tap_csv_config.py { ds }
[2025-06-25T22:29:54.365+0000] {docker.py:429} INFO - DEBUG (Tentativa 1/5): Arquivo n√£o encontrado para 'order_details' em '/opt/output_data/csv/order_details/{/file.csv'. Aguardando 2s...
[2025-06-25T22:29:54.366+0000] {docker.py:429} INFO - Traceback (most recent call last):
  File "/opt/meltano/scripts/generate_tap_csv_config.py", line 63, in <module>
[2025-06-25T22:29:54.367+0000] {docker.py:429} INFO - time.sleep(RETRY_DELAY_SECONDS)
[2025-06-25T22:29:54.369+0000] {docker.py:429} INFO - NameError: name 'time' is not defined
[2025-06-25T22:29:54.765+0000] {taskinstance.py:2698} ERROR - Task failed with exception
Traceback (most recent call last):
  File "/home/airflow/.local/lib/python3.10/site-packages/docker/api/client.py", line 265, in _raise_for_status
    response.raise_for_status()
  File "/home/airflow/.local/lib/python3.10/site-packages/requests/models.py", line 1021, in raise_for_status
    raise HTTPError(http_error_msg, response=self)
requests.exceptions.HTTPError: 400 Client Error: Bad Request for url: http+docker://localhost/v1.47/containers/create

The above exception was the direct cause of the following exception:

Traceback (most recent call last):
  File "/home/airflow/.local/lib/python3.10/site-packages/airflow/providers/docker/operators/docker.py", line 364, in _run_image
    return self._run_image_with_mounts([*self.mounts, tmp_mount], add_tmp_variable=True)
  File "/home/airflow/.local/lib/python3.10/site-packages/airflow/providers/docker/operators/docker.py", line 391, in _run_image_with_mounts
    self.container = self.cli.create_container(
  File "/home/airflow/.local/lib/python3.10/site-packages/docker/api/container.py", line 439, in create_container
    return self.create_container_from_config(config, name, platform)
  File "/home/airflow/.local/lib/python3.10/site-packages/docker/api/container.py", line 456, in create_container_from_config
    return self._result(res, True)
  File "/home/airflow/.local/lib/python3.10/site-packages/docker/api/client.py", line 271, in _result
    self._raise_for_status(response)
  File "/home/airflow/.local/lib/python3.10/site-packages/docker/api/client.py", line 267, in _raise_for_status
    raise create_api_error_from_http_exception(e) from e
  File "/home/airflow/.local/lib/python3.10/site-packages/docker/errors.py", line 39, in create_api_error_from_http_exception
    raise cls(e, response=response, explanation=explanation) from e
docker.errors.APIError: 400 Client Error for http+docker://localhost/v1.47/containers/create: Bad Request ("invalid mount config for type "bind": bind source path does not exist: /tmp/airflowtmpzgmql0mt")

During handling of the above exception, another exception occurred:

Traceback (most recent call last):
  File "/home/airflow/.local/lib/python3.10/site-packages/airflow/models/taskinstance.py", line 433, in _execute_task
    result = execute_callable(context=context, **execute_callable_kwargs)
  File "/home/airflow/.local/lib/python3.10/site-packages/airflow/providers/docker/operators/docker.py", line 502, in execute
    return self._run_image()
  File "/home/airflow/.local/lib/python3.10/site-packages/airflow/providers/docker/operators/docker.py", line 373, in _run_image
    return self._run_image_with_mounts(self.mounts, add_tmp_variable=False)
  File "/home/airflow/.local/lib/python3.10/site-packages/airflow/providers/docker/operators/docker.py", line 437, in _run_image_with_mounts
    raise DockerContainerFailedException(f"Docker container failed: {result!r}", logs=log_lines)
airflow.providers.docker.exceptions.DockerContainerFailedException: Docker container failed: {'StatusCode': 1}
[2025-06-25T22:29:54.786+0000] {taskinstance.py:1138} INFO - Marking task as UP_FOR_RETRY. dag_id=northwind, task_id=gerar_config_csv_dinamica, execution_date=20250625T222803, start_date=20250625T222934, end_date=20250625T222954
[2025-06-25T22:29:54.830+0000] {standard_task_runner.py:107} ERROR - Failed to execute job 228 for task gerar_config_csv_dinamica (Docker container failed: {'StatusCode': 1}; 190)
[2025-06-25T22:29:54.888+0000] {local_task_job_runner.py:234} INFO - Task exited with return code 1
[2025-06-25T22:29:54.917+0000] {taskinstance.py:3280} INFO - 0 downstream tasks scheduled from follow-on schedule check
