[2025-07-10T15:23:31.968+0000] {taskinstance.py:1956} INFO - Dependencies all met for dep_context=non-requeueable deps ti=<TaskInstance: northwind.gerar_csv_validacao manual__2025-07-10T15:22:25.351332+00:00 [queued]>
[2025-07-10T15:23:31.977+0000] {taskinstance.py:1956} INFO - Dependencies all met for dep_context=requeueable deps ti=<TaskInstance: northwind.gerar_csv_validacao manual__2025-07-10T15:22:25.351332+00:00 [queued]>
[2025-07-10T15:23:31.977+0000] {taskinstance.py:2170} INFO - Starting attempt 1 of 2
[2025-07-10T15:23:31.989+0000] {taskinstance.py:2191} INFO - Executing <Task(PythonOperator): gerar_csv_validacao> on 2025-07-10 15:22:25.351332+00:00
[2025-07-10T15:23:31.993+0000] {standard_task_runner.py:60} INFO - Started process 188 to run task
[2025-07-10T15:23:31.997+0000] {standard_task_runner.py:87} INFO - Running: ['***', 'tasks', 'run', 'northwind', 'gerar_csv_validacao', 'manual__2025-07-10T15:22:25.351332+00:00', '--job-id', '114', '--raw', '--subdir', 'DAGS_FOLDER/northwind.py', '--cfg-path', '/tmp/tmp6ba36p_q']
[2025-07-10T15:23:31.999+0000] {standard_task_runner.py:88} INFO - Job 114: Subtask gerar_csv_validacao
[2025-07-10T15:23:32.047+0000] {task_command.py:423} INFO - Running <TaskInstance: northwind.gerar_csv_validacao manual__2025-07-10T15:22:25.351332+00:00 [running]> on host 8ddbac0a6dc1
[2025-07-10T15:23:32.124+0000] {taskinstance.py:2480} INFO - Exporting env vars: AIRFLOW_CTX_DAG_EMAIL='lrbf@cin.ufpe.br' AIRFLOW_CTX_DAG_OWNER='***' AIRFLOW_CTX_DAG_ID='northwind' AIRFLOW_CTX_TASK_ID='gerar_csv_validacao' AIRFLOW_CTX_EXECUTION_DATE='2025-07-10T15:22:25.351332+00:00' AIRFLOW_CTX_TRY_NUMBER='1' AIRFLOW_CTX_DAG_RUN_ID='manual__2025-07-10T15:22:25.351332+00:00'
[2025-07-10T15:23:32.131+0000] {base.py:83} INFO - Using connection ID '***_target_conn' for task execution.
[2025-07-10T15:23:32.296+0000] {logging_mixin.py:188} INFO - Erro ao gerar o CSV: [Errno 13] Permission denied: '/opt/output_data/validation_query_result.csv'
[2025-07-10T15:23:32.297+0000] {taskinstance.py:2698} ERROR - Task failed with exception
Traceback (most recent call last):
  File "/home/airflow/.local/lib/python3.10/site-packages/airflow/models/taskinstance.py", line 433, in _execute_task
    result = execute_callable(context=context, **execute_callable_kwargs)
  File "/home/airflow/.local/lib/python3.10/site-packages/airflow/operators/python.py", line 199, in execute
    return_value = self.execute_callable()
  File "/home/airflow/.local/lib/python3.10/site-packages/airflow/operators/python.py", line 216, in execute_callable
    return self.python_callable(*self.op_args, **self.op_kwargs)
  File "/opt/airflow/dags/northwind.py", line 60, in _export_query_to_csv
    with open(output_path, 'w', newline='') as csvfile:
PermissionError: [Errno 13] Permission denied: '/opt/output_data/validation_query_result.csv'
[2025-07-10T15:23:32.309+0000] {taskinstance.py:1138} INFO - Marking task as UP_FOR_RETRY. dag_id=northwind, task_id=gerar_csv_validacao, execution_date=20250710T152225, start_date=20250710T152331, end_date=20250710T152332
[2025-07-10T15:23:32.322+0000] {standard_task_runner.py:107} ERROR - Failed to execute job 114 for task gerar_csv_validacao ([Errno 13] Permission denied: '/opt/output_data/validation_query_result.csv'; 188)
[2025-07-10T15:23:32.342+0000] {local_task_job_runner.py:234} INFO - Task exited with return code 1
[2025-07-10T15:23:32.356+0000] {taskinstance.py:3280} INFO - 0 downstream tasks scheduled from follow-on schedule check
