[2025-06-23T22:03:35.876+0000] {taskinstance.py:1956} INFO - Dependencies all met for dep_context=non-requeueable deps ti=<TaskInstance: northwind.gerar_config_py manual__2025-06-23T21:57:37.967108+00:00 [queued]>
[2025-06-23T22:03:35.895+0000] {taskinstance.py:1956} INFO - Dependencies all met for dep_context=requeueable deps ti=<TaskInstance: northwind.gerar_config_py manual__2025-06-23T21:57:37.967108+00:00 [queued]>
[2025-06-23T22:03:35.896+0000] {taskinstance.py:2170} INFO - Starting attempt 2 of 2
[2025-06-23T22:03:35.921+0000] {taskinstance.py:2191} INFO - Executing <Task(DockerOperator): gerar_config_py> on 2025-06-23 21:57:37.967108+00:00
[2025-06-23T22:03:35.930+0000] {standard_task_runner.py:60} INFO - Started process 261 to run task
[2025-06-23T22:03:35.935+0000] {standard_task_runner.py:87} INFO - Running: ['***', 'tasks', 'run', 'northwind', 'gerar_config_py', 'manual__2025-06-23T21:57:37.967108+00:00', '--job-id', '22', '--raw', '--subdir', 'DAGS_FOLDER/dag.py', '--cfg-path', '/tmp/tmpaw1rds5x']
[2025-06-23T22:03:35.938+0000] {standard_task_runner.py:88} INFO - Job 22: Subtask gerar_config_py
[2025-06-23T22:03:36.009+0000] {task_command.py:423} INFO - Running <TaskInstance: northwind.gerar_config_py manual__2025-06-23T21:57:37.967108+00:00 [running]> on host a06304be4538
[2025-06-23T22:03:36.127+0000] {taskinstance.py:2480} INFO - Exporting env vars: AIRFLOW_CTX_DAG_EMAIL='lrbf@cin.ufpe.br' AIRFLOW_CTX_DAG_OWNER='***' AIRFLOW_CTX_DAG_ID='northwind' AIRFLOW_CTX_TASK_ID='gerar_config_py' AIRFLOW_CTX_EXECUTION_DATE='2025-06-23T21:57:37.967108+00:00' AIRFLOW_CTX_TRY_NUMBER='2' AIRFLOW_CTX_DAG_RUN_ID='manual__2025-06-23T21:57:37.967108+00:00'
[2025-06-23T22:03:36.925+0000] {docker.py:359} INFO - Starting docker container from image indicium_pipeline-meltano:latest
[2025-06-23T22:03:39.113+0000] {docker.py:429} INFO - Running meltano install...
[2025-06-23T22:03:42.923+0000] {docker.py:429} INFO - [2m2025-06-23T22:03:42.922778Z[0m [[32m[1minfo     [0m] [1mInstalling 7 plugins          [0m
[2025-06-23T22:03:42.932+0000] {docker.py:429} INFO - [2m2025-06-23T22:03:42.932014Z[0m [[32m[1minfo     [0m] [1mInstalling extractor 'tap-postgres'[0m
[2025-06-23T22:03:42.946+0000] {docker.py:429} INFO - [2m2025-06-23T22:03:42.945542Z[0m [[32m[1minfo     [0m] [1mInstalling extractor 'tap-csv'[0m
[2025-06-23T22:03:42.962+0000] {docker.py:429} INFO - [2m2025-06-23T22:03:42.961864Z[0m [[32m[1minfo     [0m] [1mInstalling extractor 'tap-csv-latest'[0m
[2025-06-23T22:03:42.980+0000] {docker.py:429} INFO - [2m2025-06-23T22:03:42.979880Z[0m [[32m[1minfo     [0m] [1mInstalling loader 'target-postgres'[0m
[2025-06-23T22:03:43.005+0000] {docker.py:429} INFO - [2m2025-06-23T22:03:43.004559Z[0m [[32m[1minfo     [0m] [1mInstalling loader 'target-csv'[0m
[2025-06-23T22:03:43.036+0000] {docker.py:429} INFO - [2m2025-06-23T22:03:43.035662Z[0m [[32m[1minfo     [0m] [1mInstalling loader 'target-csv-postgres'[0m
[2025-06-23T22:03:43.073+0000] {docker.py:429} INFO - [2m2025-06-23T22:03:43.071680Z[0m [[32m[1minfo     [0m] [1mInstalling loader 'target-csv-csv'[0m
[2025-06-23T22:03:46.096+0000] {docker.py:429} INFO - [2m2025-06-23T22:03:46.096141Z[0m [[32m[1minfo     [0m] [1mInstalled extractor 'tap-postgres'[0m
[2025-06-23T22:03:46.102+0000] {docker.py:429} INFO - [2m2025-06-23T22:03:46.101354Z[0m [[32m[1minfo     [0m] [1mInstalled loader 'target-postgres'[0m
[2025-06-23T22:03:53.481+0000] {docker.py:429} INFO - [2m2025-06-23T22:03:53.480718Z[0m [[32m[1minfo     [0m] [1mInstalled extractor 'tap-csv-latest'[0m
[2025-06-23T22:03:53.617+0000] {docker.py:429} INFO - [2m2025-06-23T22:03:53.617000Z[0m [[32m[1minfo     [0m] [1mInstalled extractor 'tap-csv' [0m
[2025-06-23T22:03:53.869+0000] {docker.py:429} INFO - [2m2025-06-23T22:03:53.868318Z[0m [[32m[1minfo     [0m] [1mInstalled loader 'target-csv' [0m
[2025-06-23T22:03:53.990+0000] {docker.py:429} INFO - [2m2025-06-23T22:03:53.989454Z[0m [[32m[1minfo     [0m] [1mInstalled loader 'target-csv-csv'[0m
[2025-06-23T22:03:54.081+0000] {docker.py:429} INFO - [2m2025-06-23T22:03:54.080256Z[0m [[32m[1minfo     [0m] [1mInstalled loader 'target-csv-postgres'[0m
[2025-06-23T22:03:54.081+0000] {docker.py:429} INFO - [2m2025-06-23T22:03:54.080786Z[0m [[32m[1minfo     [0m] [1mInstalled 7/7 plugins         [0m
[2025-06-23T22:03:55.341+0000] {docker.py:429} INFO - Meltano install completed. Executing command: python3 scripts/generate_csv_config.py
[2025-06-23T22:03:55.360+0000] {docker.py:429} INFO - Traceback (most recent call last):
  File "/opt/meltano/scripts/generate_csv_config.py", line 17, in <module>
    latest_date_path = max([d for d in csv_base.iterdir() if d.is_dir()], key=os.path.getmtime, default=None)
  File "/opt/meltano/scripts/generate_csv_config.py", line 17, in <listcomp>
    latest_date_path = max([d for d in csv_base.iterdir() if d.is_dir()], key=os.path.getmtime, default=None)
  File "/usr/local/lib/python3.10/pathlib.py", line 1017, in iterdir
[2025-06-23T22:03:55.361+0000] {docker.py:429} INFO - for name in self._accessor.listdir(self):
FileNotFoundError: [Errno 2] No such file or directory: '/opt/data/csv/order_details'
[2025-06-23T22:03:55.736+0000] {taskinstance.py:2698} ERROR - Task failed with exception
Traceback (most recent call last):
  File "/home/airflow/.local/lib/python3.10/site-packages/airflow/models/taskinstance.py", line 433, in _execute_task
    result = execute_callable(context=context, **execute_callable_kwargs)
  File "/home/airflow/.local/lib/python3.10/site-packages/airflow/providers/docker/operators/docker.py", line 502, in execute
    return self._run_image()
  File "/home/airflow/.local/lib/python3.10/site-packages/airflow/providers/docker/operators/docker.py", line 376, in _run_image
    return self._run_image_with_mounts(self.mounts, add_tmp_variable=False)
  File "/home/airflow/.local/lib/python3.10/site-packages/airflow/providers/docker/operators/docker.py", line 437, in _run_image_with_mounts
    raise DockerContainerFailedException(f"Docker container failed: {result!r}", logs=log_lines)
airflow.providers.docker.exceptions.DockerContainerFailedException: Docker container failed: {'StatusCode': 1}
[2025-06-23T22:03:55.747+0000] {taskinstance.py:1138} INFO - Marking task as FAILED. dag_id=northwind, task_id=gerar_config_py, execution_date=20250623T215737, start_date=20250623T220335, end_date=20250623T220355
[2025-06-23T22:03:55.838+0000] {logging_mixin.py:188} WARNING - /home/***/.local/lib/python3.10/site-packages/***/utils/email.py:154 RemovedInAirflow3Warning: Fetching SMTP credentials from configuration variables will be deprecated in a future release. Please set credentials using a connection instead.
[2025-06-23T22:03:55.839+0000] {configuration.py:1046} WARNING - section/key [smtp/smtp_user] not found in config
[2025-06-23T22:03:55.839+0000] {email.py:270} INFO - Email alerting: attempt 1
[2025-06-23T22:03:55.855+0000] {configuration.py:1046} WARNING - section/key [smtp/smtp_user] not found in config
[2025-06-23T22:03:55.856+0000] {email.py:270} INFO - Email alerting: attempt 1
[2025-06-23T22:03:55.857+0000] {taskinstance.py:826} ERROR - Failed to send email to: ['lrbf@cin.ufpe.br']
Traceback (most recent call last):
  File "/home/airflow/.local/lib/python3.10/site-packages/airflow/models/taskinstance.py", line 2334, in _run_raw_task
    self._execute_task_with_callbacks(context, test_mode, session=session)
  File "/home/airflow/.local/lib/python3.10/site-packages/airflow/models/taskinstance.py", line 2499, in _execute_task_with_callbacks
    result = self._execute_task(context, task_orig)
  File "/home/airflow/.local/lib/python3.10/site-packages/airflow/models/taskinstance.py", line 2516, in _execute_task
    return _execute_task(self, context, task_orig)
  File "/home/airflow/.local/lib/python3.10/site-packages/airflow/models/taskinstance.py", line 433, in _execute_task
    result = execute_callable(context=context, **execute_callable_kwargs)
  File "/home/airflow/.local/lib/python3.10/site-packages/airflow/providers/docker/operators/docker.py", line 502, in execute
    return self._run_image()
  File "/home/airflow/.local/lib/python3.10/site-packages/airflow/providers/docker/operators/docker.py", line 376, in _run_image
    return self._run_image_with_mounts(self.mounts, add_tmp_variable=False)
  File "/home/airflow/.local/lib/python3.10/site-packages/airflow/providers/docker/operators/docker.py", line 437, in _run_image_with_mounts
    raise DockerContainerFailedException(f"Docker container failed: {result!r}", logs=log_lines)
airflow.providers.docker.exceptions.DockerContainerFailedException: Docker container failed: {'StatusCode': 1}

During handling of the above exception, another exception occurred:

Traceback (most recent call last):
  File "/home/airflow/.local/lib/python3.10/site-packages/airflow/models/taskinstance.py", line 1000, in _email_alert
    send_email(task.email, subject, html_content)
  File "/home/airflow/.local/lib/python3.10/site-packages/airflow/utils/email.py", line 80, in send_email
    return backend(
  File "/home/airflow/.local/lib/python3.10/site-packages/airflow/utils/email.py", line 154, in send_email_smtp
    send_mime_email(e_from=mail_from, e_to=recipients, mime_msg=msg, conn_id=conn_id, dryrun=dryrun)
  File "/home/airflow/.local/lib/python3.10/site-packages/airflow/utils/email.py", line 272, in send_mime_email
    smtp_conn = _get_smtp_connection(smtp_host, smtp_port, smtp_timeout, smtp_ssl)
  File "/home/airflow/.local/lib/python3.10/site-packages/airflow/utils/email.py", line 316, in _get_smtp_connection
    return smtplib.SMTP(host=host, port=port, timeout=timeout)
  File "/usr/local/lib/python3.10/smtplib.py", line 255, in __init__
    (code, msg) = self.connect(host, port)
  File "/usr/local/lib/python3.10/smtplib.py", line 341, in connect
    self.sock = self._get_socket(host, port, self.timeout)
  File "/usr/local/lib/python3.10/smtplib.py", line 312, in _get_socket
    return socket.create_connection((host, port), timeout,
  File "/usr/local/lib/python3.10/socket.py", line 845, in create_connection
    raise err
  File "/usr/local/lib/python3.10/socket.py", line 833, in create_connection
    sock.connect(sa)
ConnectionRefusedError: [Errno 111] Connection refused

During handling of the above exception, another exception occurred:

Traceback (most recent call last):
  File "/home/airflow/.local/lib/python3.10/site-packages/airflow/models/taskinstance.py", line 824, in _handle_failure
    task_instance.email_alert(error, failure_context["task"])
  File "/home/airflow/.local/lib/python3.10/site-packages/airflow/models/taskinstance.py", line 2946, in email_alert
    _email_alert(task_instance=self, exception=exception, task=task)
  File "/home/airflow/.local/lib/python3.10/site-packages/airflow/models/taskinstance.py", line 1002, in _email_alert
    send_email(task.email, subject, html_content_err)
  File "/home/airflow/.local/lib/python3.10/site-packages/airflow/utils/email.py", line 80, in send_email
    return backend(
  File "/home/airflow/.local/lib/python3.10/site-packages/airflow/utils/email.py", line 154, in send_email_smtp
    send_mime_email(e_from=mail_from, e_to=recipients, mime_msg=msg, conn_id=conn_id, dryrun=dryrun)
  File "/home/airflow/.local/lib/python3.10/site-packages/airflow/utils/email.py", line 272, in send_mime_email
    smtp_conn = _get_smtp_connection(smtp_host, smtp_port, smtp_timeout, smtp_ssl)
  File "/home/airflow/.local/lib/python3.10/site-packages/airflow/utils/email.py", line 316, in _get_smtp_connection
    return smtplib.SMTP(host=host, port=port, timeout=timeout)
  File "/usr/local/lib/python3.10/smtplib.py", line 255, in __init__
    (code, msg) = self.connect(host, port)
  File "/usr/local/lib/python3.10/smtplib.py", line 341, in connect
    self.sock = self._get_socket(host, port, self.timeout)
  File "/usr/local/lib/python3.10/smtplib.py", line 312, in _get_socket
    return socket.create_connection((host, port), timeout,
  File "/usr/local/lib/python3.10/socket.py", line 845, in create_connection
    raise err
  File "/usr/local/lib/python3.10/socket.py", line 833, in create_connection
    sock.connect(sa)
ConnectionRefusedError: [Errno 111] Connection refused
[2025-06-23T22:03:55.888+0000] {standard_task_runner.py:107} ERROR - Failed to execute job 22 for task gerar_config_py (Docker container failed: {'StatusCode': 1}; 261)
[2025-06-23T22:03:55.913+0000] {local_task_job_runner.py:234} INFO - Task exited with return code 1
[2025-06-23T22:03:55.951+0000] {taskinstance.py:3280} INFO - 0 downstream tasks scheduled from follow-on schedule check
