[2025-06-26T17:56:42.356+0000] {taskinstance.py:1956} INFO - Dependencies all met for dep_context=non-requeueable deps ti=<TaskInstance: northwind.carregamento_postgres manual__2025-06-26T17:48:49.323327+00:00 [queued]>
[2025-06-26T17:56:42.373+0000] {taskinstance.py:1956} INFO - Dependencies all met for dep_context=requeueable deps ti=<TaskInstance: northwind.carregamento_postgres manual__2025-06-26T17:48:49.323327+00:00 [queued]>
[2025-06-26T17:56:42.373+0000] {taskinstance.py:2170} INFO - Starting attempt 2 of 2
[2025-06-26T17:56:42.388+0000] {taskinstance.py:2191} INFO - Executing <Task(DockerOperator): carregamento_postgres> on 2025-06-26 17:48:49.323327+00:00
[2025-06-26T17:56:42.399+0000] {standard_task_runner.py:60} INFO - Started process 170 to run task
[2025-06-26T17:56:42.425+0000] {standard_task_runner.py:87} INFO - Running: ['***', 'tasks', 'run', 'northwind', 'carregamento_postgres', 'manual__2025-06-26T17:48:49.323327+00:00', '--job-id', '317', '--raw', '--subdir', 'DAGS_FOLDER/dag.py', '--cfg-path', '/tmp/tmpl9k6rncc']
[2025-06-26T17:56:42.441+0000] {standard_task_runner.py:88} INFO - Job 317: Subtask carregamento_postgres
[2025-06-26T17:56:42.555+0000] {task_command.py:423} INFO - Running <TaskInstance: northwind.carregamento_postgres manual__2025-06-26T17:48:49.323327+00:00 [running]> on host 6afc1f3750fb
[2025-06-26T17:56:42.629+0000] {abstractoperator.py:707} ERROR - Exception rendering Jinja template for task 'carregamento_postgres', field 'command'. Template: ['bash', '/opt/meltano/scripts/load_meltano.sh', '{{ task_instance.xcom_pull(task_ids=\'gerar_config_csv_dinamica\') | tojson | replace(\'"\', \'\\"\') }}', '{{ task_instance.xcom_pull(task_ids=\'gerar_config_target_postgres_dinamica\') | tojson | replace(\'"\', \'\\"\') }}']
Traceback (most recent call last):
  File "/home/airflow/.local/lib/python3.10/site-packages/airflow/models/abstractoperator.py", line 699, in _do_render_template_fields
    rendered_content = self.render_template(
  File "/home/airflow/.local/lib/python3.10/site-packages/airflow/template/templater.py", line 184, in render_template
    return [self.render_template(element, context, jinja_env, oids) for element in value]
  File "/home/airflow/.local/lib/python3.10/site-packages/airflow/template/templater.py", line 184, in <listcomp>
    return [self.render_template(element, context, jinja_env, oids) for element in value]
  File "/home/airflow/.local/lib/python3.10/site-packages/airflow/template/templater.py", line 171, in render_template
    template = jinja_env.get_template(value)
  File "/home/airflow/.local/lib/python3.10/site-packages/jinja2/environment.py", line 1010, in get_template
    return self._load_template(name, globals)
  File "/home/airflow/.local/lib/python3.10/site-packages/jinja2/environment.py", line 969, in _load_template
    template = self.loader.load(self, name, self.make_globals(globals))
  File "/home/airflow/.local/lib/python3.10/site-packages/jinja2/loaders.py", line 125, in load
    source, filename, uptodate = self.get_source(environment, name)
  File "/home/airflow/.local/lib/python3.10/site-packages/jinja2/loaders.py", line 204, in get_source
    raise TemplateNotFound(template)
jinja2.exceptions.TemplateNotFound: /opt/meltano/scripts/load_meltano.sh
[2025-06-26T17:56:42.633+0000] {taskinstance.py:2698} ERROR - Task failed with exception
Traceback (most recent call last):
  File "/home/airflow/.local/lib/python3.10/site-packages/airflow/models/taskinstance.py", line 2334, in _run_raw_task
    self._execute_task_with_callbacks(context, test_mode, session=session)
  File "/home/airflow/.local/lib/python3.10/site-packages/airflow/models/taskinstance.py", line 2465, in _execute_task_with_callbacks
    task_orig = self.render_templates(context=context)
  File "/home/airflow/.local/lib/python3.10/site-packages/airflow/models/taskinstance.py", line 2877, in render_templates
    original_task.render_template_fields(context)
  File "/home/airflow/.local/lib/python3.10/site-packages/airflow/models/baseoperator.py", line 1241, in render_template_fields
    self._do_render_template_fields(self, self.template_fields, context, jinja_env, set())
  File "/home/airflow/.local/lib/python3.10/site-packages/airflow/utils/session.py", line 79, in wrapper
    return func(*args, session=session, **kwargs)
  File "/home/airflow/.local/lib/python3.10/site-packages/airflow/models/abstractoperator.py", line 699, in _do_render_template_fields
    rendered_content = self.render_template(
  File "/home/airflow/.local/lib/python3.10/site-packages/airflow/template/templater.py", line 184, in render_template
    return [self.render_template(element, context, jinja_env, oids) for element in value]
  File "/home/airflow/.local/lib/python3.10/site-packages/airflow/template/templater.py", line 184, in <listcomp>
    return [self.render_template(element, context, jinja_env, oids) for element in value]
  File "/home/airflow/.local/lib/python3.10/site-packages/airflow/template/templater.py", line 171, in render_template
    template = jinja_env.get_template(value)
  File "/home/airflow/.local/lib/python3.10/site-packages/jinja2/environment.py", line 1010, in get_template
    return self._load_template(name, globals)
  File "/home/airflow/.local/lib/python3.10/site-packages/jinja2/environment.py", line 969, in _load_template
    template = self.loader.load(self, name, self.make_globals(globals))
  File "/home/airflow/.local/lib/python3.10/site-packages/jinja2/loaders.py", line 125, in load
    source, filename, uptodate = self.get_source(environment, name)
  File "/home/airflow/.local/lib/python3.10/site-packages/jinja2/loaders.py", line 204, in get_source
    raise TemplateNotFound(template)
jinja2.exceptions.TemplateNotFound: /opt/meltano/scripts/load_meltano.sh
[2025-06-26T17:56:42.658+0000] {taskinstance.py:1138} INFO - Marking task as FAILED. dag_id=northwind, task_id=carregamento_postgres, execution_date=20250626T174849, start_date=20250626T175642, end_date=20250626T175642
[2025-06-26T17:56:42.715+0000] {logging_mixin.py:188} WARNING - /home/***/.local/lib/python3.10/site-packages/***/utils/email.py:154 RemovedInAirflow3Warning: Fetching SMTP credentials from configuration variables will be deprecated in a future release. Please set credentials using a connection instead.
[2025-06-26T17:56:42.716+0000] {configuration.py:1046} WARNING - section/key [smtp/smtp_user] not found in config
[2025-06-26T17:56:42.716+0000] {email.py:270} INFO - Email alerting: attempt 1
[2025-06-26T17:56:42.734+0000] {configuration.py:1046} WARNING - section/key [smtp/smtp_user] not found in config
[2025-06-26T17:56:42.735+0000] {email.py:270} INFO - Email alerting: attempt 1
[2025-06-26T17:56:42.737+0000] {taskinstance.py:826} ERROR - Failed to send email to: ['lrbf@cin.ufpe.br']
Traceback (most recent call last):
  File "/home/airflow/.local/lib/python3.10/site-packages/airflow/models/taskinstance.py", line 2334, in _run_raw_task
    self._execute_task_with_callbacks(context, test_mode, session=session)
  File "/home/airflow/.local/lib/python3.10/site-packages/airflow/models/taskinstance.py", line 2465, in _execute_task_with_callbacks
    task_orig = self.render_templates(context=context)
  File "/home/airflow/.local/lib/python3.10/site-packages/airflow/models/taskinstance.py", line 2877, in render_templates
    original_task.render_template_fields(context)
  File "/home/airflow/.local/lib/python3.10/site-packages/airflow/models/baseoperator.py", line 1241, in render_template_fields
    self._do_render_template_fields(self, self.template_fields, context, jinja_env, set())
  File "/home/airflow/.local/lib/python3.10/site-packages/airflow/utils/session.py", line 79, in wrapper
    return func(*args, session=session, **kwargs)
  File "/home/airflow/.local/lib/python3.10/site-packages/airflow/models/abstractoperator.py", line 699, in _do_render_template_fields
    rendered_content = self.render_template(
  File "/home/airflow/.local/lib/python3.10/site-packages/airflow/template/templater.py", line 184, in render_template
    return [self.render_template(element, context, jinja_env, oids) for element in value]
  File "/home/airflow/.local/lib/python3.10/site-packages/airflow/template/templater.py", line 184, in <listcomp>
    return [self.render_template(element, context, jinja_env, oids) for element in value]
  File "/home/airflow/.local/lib/python3.10/site-packages/airflow/template/templater.py", line 171, in render_template
    template = jinja_env.get_template(value)
  File "/home/airflow/.local/lib/python3.10/site-packages/jinja2/environment.py", line 1010, in get_template
    return self._load_template(name, globals)
  File "/home/airflow/.local/lib/python3.10/site-packages/jinja2/environment.py", line 969, in _load_template
    template = self.loader.load(self, name, self.make_globals(globals))
  File "/home/airflow/.local/lib/python3.10/site-packages/jinja2/loaders.py", line 125, in load
    source, filename, uptodate = self.get_source(environment, name)
  File "/home/airflow/.local/lib/python3.10/site-packages/jinja2/loaders.py", line 204, in get_source
    raise TemplateNotFound(template)
jinja2.exceptions.TemplateNotFound: /opt/meltano/scripts/load_meltano.sh

During handling of the above exception, another exception occurred:

Traceback (most recent call last):
  File "/home/airflow/.local/lib/python3.10/site-packages/airflow/models/taskinstance.py", line 1000, in _email_alert
    send_email(task.email, subject, html_content)
  File "/home/airflow/.local/lib/python3.10/site-packages/airflow/utils/email.py", line 80, in send_email
    return backend(
  File "/home/airflow/.local/lib/python3.10/site-packages/airflow/utils/email.py", line 154, in send_email_smtp
    send_mime_email(e_from=mail_from, e_to=recipients, mime_msg=msg, conn_id=conn_id, dryrun=dryrun)
  File "/home/airflow/.local/lib/python3.10/site-packages/airflow/utils/email.py", line 272, in send_mime_email
    smtp_conn = _get_smtp_connection(smtp_host, smtp_port, smtp_timeout, smtp_ssl)
  File "/home/airflow/.local/lib/python3.10/site-packages/airflow/utils/email.py", line 316, in _get_smtp_connection
    return smtplib.SMTP(host=host, port=port, timeout=timeout)
  File "/usr/local/lib/python3.10/smtplib.py", line 255, in __init__
    (code, msg) = self.connect(host, port)
  File "/usr/local/lib/python3.10/smtplib.py", line 341, in connect
    self.sock = self._get_socket(host, port, self.timeout)
  File "/usr/local/lib/python3.10/smtplib.py", line 312, in _get_socket
    return socket.create_connection((host, port), timeout,
  File "/usr/local/lib/python3.10/socket.py", line 845, in create_connection
    raise err
  File "/usr/local/lib/python3.10/socket.py", line 833, in create_connection
    sock.connect(sa)
ConnectionRefusedError: [Errno 111] Connection refused

During handling of the above exception, another exception occurred:

Traceback (most recent call last):
  File "/home/airflow/.local/lib/python3.10/site-packages/airflow/models/taskinstance.py", line 824, in _handle_failure
    task_instance.email_alert(error, failure_context["task"])
  File "/home/airflow/.local/lib/python3.10/site-packages/airflow/models/taskinstance.py", line 2946, in email_alert
    _email_alert(task_instance=self, exception=exception, task=task)
  File "/home/airflow/.local/lib/python3.10/site-packages/airflow/models/taskinstance.py", line 1002, in _email_alert
    send_email(task.email, subject, html_content_err)
  File "/home/airflow/.local/lib/python3.10/site-packages/airflow/utils/email.py", line 80, in send_email
    return backend(
  File "/home/airflow/.local/lib/python3.10/site-packages/airflow/utils/email.py", line 154, in send_email_smtp
    send_mime_email(e_from=mail_from, e_to=recipients, mime_msg=msg, conn_id=conn_id, dryrun=dryrun)
  File "/home/airflow/.local/lib/python3.10/site-packages/airflow/utils/email.py", line 272, in send_mime_email
    smtp_conn = _get_smtp_connection(smtp_host, smtp_port, smtp_timeout, smtp_ssl)
  File "/home/airflow/.local/lib/python3.10/site-packages/airflow/utils/email.py", line 316, in _get_smtp_connection
    return smtplib.SMTP(host=host, port=port, timeout=timeout)
  File "/usr/local/lib/python3.10/smtplib.py", line 255, in __init__
    (code, msg) = self.connect(host, port)
  File "/usr/local/lib/python3.10/smtplib.py", line 341, in connect
    self.sock = self._get_socket(host, port, self.timeout)
  File "/usr/local/lib/python3.10/smtplib.py", line 312, in _get_socket
    return socket.create_connection((host, port), timeout,
  File "/usr/local/lib/python3.10/socket.py", line 845, in create_connection
    raise err
  File "/usr/local/lib/python3.10/socket.py", line 833, in create_connection
    sock.connect(sa)
ConnectionRefusedError: [Errno 111] Connection refused
[2025-06-26T17:56:42.769+0000] {standard_task_runner.py:107} ERROR - Failed to execute job 317 for task carregamento_postgres (/opt/meltano/scripts/load_meltano.sh; 170)
[2025-06-26T17:56:42.808+0000] {local_task_job_runner.py:234} INFO - Task exited with return code 1
[2025-06-26T17:56:42.846+0000] {taskinstance.py:3280} INFO - 0 downstream tasks scheduled from follow-on schedule check
